2022-05-23 13:24:47.251 | INFO     | __main__:server:72 - 启动服务：192.168.23.1:60909
2022-05-23 13:24:47.256 | INFO     | __main__:server:75 - 服务注册开始
2022-05-23 13:24:47.348 | INFO     | __main__:server:82 - 服务注册成功
2022-05-23 13:24:49.253 | ERROR    | grpc._server:_call_behavior:443 - An error has been caught in function '_call_behavior', process 'MainProcess' (5092), thread 'ThreadPoolExecutor-0_0' (12584):
Traceback (most recent call last):

  File "C:\Users\admin\AppData\Local\Programs\Python\Python37\lib\threading.py", line 890, in _bootstrap
    self._bootstrap_inner()
    │    └ <function Thread._bootstrap_inner at 0x00000259B0D9FAF8>
    └ <Thread(ThreadPoolExecutor-0_0, started daemon 12584)>

  File "C:\Users\admin\AppData\Local\Programs\Python\Python37\lib\threading.py", line 926, in _bootstrap_inner
    self.run()
    │    └ <function Thread.run at 0x00000259B0D9F8B8>
    └ <Thread(ThreadPoolExecutor-0_0, started daemon 12584)>

  File "C:\Users\admin\AppData\Local\Programs\Python\Python37\lib\threading.py", line 870, in run
    self._target(*self._args, **self._kwargs)
    │    │        │    │        │    └ {}
    │    │        │    │        └ <Thread(ThreadPoolExecutor-0_0, started daemon 12584)>
    │    │        │    └ (<weakref at 0x00000259B3B0EE08; to 'ThreadPoolExecutor' at 0x00000259B3886A08>, <_queue.SimpleQueue object at 0x00000259B389...
    │    │        └ <Thread(ThreadPoolExecutor-0_0, started daemon 12584)>
    │    └ <function _worker at 0x00000259B38A5828>
    └ <Thread(ThreadPoolExecutor-0_0, started daemon 12584)>

  File "C:\Users\admin\AppData\Local\Programs\Python\Python37\lib\concurrent\futures\thread.py", line 80, in _worker
    work_item.run()
    │         └ <function _WorkItem.run at 0x00000259B38A5948>
    └ <concurrent.futures.thread._WorkItem object at 0x00000259B3AFDC48>

  File "C:\Users\admin\AppData\Local\Programs\Python\Python37\lib\concurrent\futures\thread.py", line 57, in run
    result = self.fn(*self.args, **self.kwargs)
             │    │   │    │       │    └ {}
             │    │   │    │       └ <concurrent.futures.thread._WorkItem object at 0x00000259B3AFDC48>
             │    │   │    └ [<grpc._cython.cygrpc.RequestCallEvent object at 0x00000259B3B0E9F8>, <grpc._server._RPCState object at 0x00000259B3886788>, ...
             │    │   └ <concurrent.futures.thread._WorkItem object at 0x00000259B3AFDC48>
             │    └ <function _unary_response_in_pool at 0x00000259B38D9048>
             └ <concurrent.futures.thread._WorkItem object at 0x00000259B3AFDC48>

  File "D:\virtual-environment\py3.7\lib\site-packages\grpc\_server.py", line 561, in _unary_response_in_pool
    argument, request_deserializer)
    │         └ <built-in method FromString of GeneratedProtocolMessageType object at 0x00000259B0B8C838>
    └

> File "D:\virtual-environment\py3.7\lib\site-packages\grpc\_server.py", line 443, in _call_behavior
    response_or_iterator = behavior(argument, context)
                           │        │         └ <grpc._server._Context object at 0x00000259B3B07B48>
                           │        └ 
                           └ <bound method GoodsServicer.CategoryBrandList of <goods_srv.handler.goods.GoodsServicer object at 0x00000259B38942C8>>

  File "D:\PythonProjects\shop\goods_srv\handler\goods.py", line 531, in CategoryBrandList
    category_brand_rsp.category.parentCategory = category_brand.category.parent_category
    │                  │                         │              └ <peewee.ForeignKeyAccessor object at 0x00000259B35A5C08>
    │                  │                         └ <GoodsCategoryBrand: 12>
    │                  └ <field property 'CategoryBrandResponse.category'>
    └ id: 12
      brand {
        id: 628
        name: "\346\266\265\346\236\234"
        logo: "https://img30.360buyimg.com/popshop/jfs/t1/10755/20/8366...

TypeError: None has type NoneType, but expected one of: int, long
2022-05-23 13:31:21.397 | INFO     | __main__:on_exit:41 - 注销a935fa90-da58-11ec-8d03-5a00e3ca956d服务
2022-05-23 13:31:21.529 | INFO     | __main__:on_exit:43 - 服务注销成功
