2022-05-22 14:32:12.771 | INFO     | __main__:server:72 - 启动服务：192.168.23.1:54290
2022-05-22 14:32:12.776 | INFO     | __main__:server:75 - 服务注册开始
2022-05-22 14:32:12.796 | INFO     | __main__:server:82 - 服务注册成功
2022-05-22 16:33:38.972 | ERROR    | grpc._server:_call_behavior:443 - An error has been caught in function '_call_behavior', process 'MainProcess' (13736), thread 'ThreadPoolExecutor-0_9' (10496):
Traceback (most recent call last):

  File "C:\Users\admin\AppData\Local\Programs\Python\Python37\lib\threading.py", line 890, in _bootstrap
    self._bootstrap_inner()
    │    └ <function Thread._bootstrap_inner at 0x00000269BE8FFAF8>
    └ <Thread(ThreadPoolExecutor-0_9, started daemon 10496)>

  File "C:\Users\admin\AppData\Local\Programs\Python\Python37\lib\threading.py", line 926, in _bootstrap_inner
    self.run()
    │    └ <function Thread.run at 0x00000269BE8FF8B8>
    └ <Thread(ThreadPoolExecutor-0_9, started daemon 10496)>

  File "C:\Users\admin\AppData\Local\Programs\Python\Python37\lib\threading.py", line 870, in run
    self._target(*self._args, **self._kwargs)
    │    │        │    │        │    └ {}
    │    │        │    │        └ <Thread(ThreadPoolExecutor-0_9, started daemon 10496)>
    │    │        │    └ (<weakref at 0x00000269C1385778; to 'ThreadPoolExecutor' at 0x00000269C12006C8>, <_queue.SimpleQueue object at 0x00000269C11F...
    │    │        └ <Thread(ThreadPoolExecutor-0_9, started daemon 10496)>
    │    └ <function _worker at 0x00000269C1208948>
    └ <Thread(ThreadPoolExecutor-0_9, started daemon 10496)>

  File "C:\Users\admin\AppData\Local\Programs\Python\Python37\lib\concurrent\futures\thread.py", line 80, in _worker
    work_item.run()
    │         └ <function _WorkItem.run at 0x00000269C1208A68>
    └ <concurrent.futures.thread._WorkItem object at 0x00000269C11F2D48>

  File "C:\Users\admin\AppData\Local\Programs\Python\Python37\lib\concurrent\futures\thread.py", line 57, in run
    result = self.fn(*self.args, **self.kwargs)
             │    │   │    │       │    └ {}
             │    │   │    │       └ <concurrent.futures.thread._WorkItem object at 0x00000269C11F2D48>
             │    │   │    └ [<grpc._cython.cygrpc.RequestCallEvent object at 0x00000269C13A69A8>, <grpc._server._RPCState object at 0x00000269C11F2148>, ...
             │    │   └ <concurrent.futures.thread._WorkItem object at 0x00000269C11F2D48>
             │    └ <function _unary_response_in_pool at 0x00000269C12370D8>
             └ <concurrent.futures.thread._WorkItem object at 0x00000269C11F2D48>

  File "D:\virtual-environment\py3.7\lib\site-packages\grpc\_server.py", line 561, in _unary_response_in_pool
    argument, request_deserializer)
    │         └ <built-in method FromString of GeneratedProtocolMessageType object at 0x00000269C0611398>
    └

> File "D:\virtual-environment\py3.7\lib\site-packages\grpc\_server.py", line 443, in _call_behavior
    response_or_iterator = behavior(argument, context)
                           │        │         └ <grpc._server._Context object at 0x00000269C11F2EC8>
                           │        └ 
                           └ <bound method GoodsServicer.CategoryBrandList of <goods_srv.handler.goods.GoodsServicer object at 0x00000269C1206AC8>>

  File "D:\PythonProjects\shop\goods_srv\handler\goods.py", line 531, in CategoryBrandList
    category_brand_rsp.category.parentCategory = category_brand.category.parent_category_id
    │                  │                         │              └ <peewee.ForeignKeyAccessor object at 0x00000269C0F04B48>
    │                  │                         └ <GoodsCategoryBrand: 12>
    │                  └ <field property 'CategoryBrandResponse.category'>
    └ id: 12
      brand {
        id: 628
        name: "\346\266\265\346\236\234"
        logo: "https://img30.360buyimg.com/popshop/jfs/t1/10755/20/8366...

TypeError: None has type NoneType, but expected one of: int, long
