2022-05-23 14:02:37.074 | INFO     | __main__:server:72 - 启动服务：192.168.23.1:50325
2022-05-23 14:02:37.080 | INFO     | __main__:server:75 - 服务注册开始
2022-05-23 14:02:37.127 | INFO     | __main__:server:82 - 服务注册成功
2022-05-23 14:06:17.935 | ERROR    | grpc._server:_call_behavior:443 - An error has been caught in function '_call_behavior', process 'MainProcess' (11464), thread 'ThreadPoolExecutor-0_7' (8844):
Traceback (most recent call last):

  File "C:\Users\admin\AppData\Local\Programs\Python\Python37\lib\threading.py", line 890, in _bootstrap
    self._bootstrap_inner()
    │    └ <function Thread._bootstrap_inner at 0x000002AB1AEEFAF8>
    └ <Thread(ThreadPoolExecutor-0_7, started daemon 8844)>

  File "C:\Users\admin\AppData\Local\Programs\Python\Python37\lib\threading.py", line 926, in _bootstrap_inner
    self.run()
    │    └ <function Thread.run at 0x000002AB1AEEF8B8>
    └ <Thread(ThreadPoolExecutor-0_7, started daemon 8844)>

  File "C:\Users\admin\AppData\Local\Programs\Python\Python37\lib\threading.py", line 870, in run
    self._target(*self._args, **self._kwargs)
    │    │        │    │        │    └ {}
    │    │        │    │        └ <Thread(ThreadPoolExecutor-0_7, started daemon 8844)>
    │    │        │    └ (<weakref at 0x000002AB1D9940E8; to 'ThreadPoolExecutor' at 0x000002AB1D7D68C8>, <_queue.SimpleQueue object at 0x000002AB1D7E...
    │    │        └ <Thread(ThreadPoolExecutor-0_7, started daemon 8844)>
    │    └ <function _worker at 0x000002AB1D7F5828>
    └ <Thread(ThreadPoolExecutor-0_7, started daemon 8844)>

  File "C:\Users\admin\AppData\Local\Programs\Python\Python37\lib\concurrent\futures\thread.py", line 80, in _worker
    work_item.run()
    │         └ <function _WorkItem.run at 0x000002AB1D7F5948>
    └ <concurrent.futures.thread._WorkItem object at 0x000002AB1D99E988>

  File "C:\Users\admin\AppData\Local\Programs\Python\Python37\lib\concurrent\futures\thread.py", line 57, in run
    result = self.fn(*self.args, **self.kwargs)
             │    │   │    │       │    └ {}
             │    │   │    │       └ <concurrent.futures.thread._WorkItem object at 0x000002AB1D99E988>
             │    │   │    └ [<grpc._cython.cygrpc.RequestCallEvent object at 0x000002AB1D99A408>, <grpc._server._RPCState object at 0x000002AB1D99E348>, ...
             │    │   └ <concurrent.futures.thread._WorkItem object at 0x000002AB1D99E988>
             │    └ <function _unary_response_in_pool at 0x000002AB1D82A048>
             └ <concurrent.futures.thread._WorkItem object at 0x000002AB1D99E988>

  File "D:\virtual-environment\py3.7\lib\site-packages\grpc\_server.py", line 561, in _unary_response_in_pool
    argument, request_deserializer)
    │         └ <built-in method FromString of GeneratedProtocolMessageType object at 0x000002AB1AE39968>
    └ id: 136678

> File "D:\virtual-environment\py3.7\lib\site-packages\grpc\_server.py", line 443, in _call_behavior
    response_or_iterator = behavior(argument, context)
                           │        │         └ <grpc._server._Context object at 0x000002AB1D99E6C8>
                           │        └ id: 136678
                           │          
                           └ <bound method GoodsServicer.GetCategoryBrandList of <goods_srv.handler.goods.GoodsServicer object at 0x000002AB1D7E3088>>

  File "D:\PythonProjects\shop\goods_srv\handler\goods.py", line 545, in GetCategoryBrandList
    category_brands = GoodsCategoryBrand.select().where(GoodsCategoryBrand.category == category)
                      │                  │              │                              └ <Category: 136678>
                      │                  │              └ <Model: GoodsCategoryBrand>
                      │                  └ <classmethod object at 0x000002AB1D4C2FC8>
                      └ <Model: GoodsCategoryBrand>

AttributeError: type object 'GoodsCategoryBrand' has no attribute 'category'
2022-05-23 14:17:00.667 | INFO     | __main__:on_exit:41 - 注销f221926e-da5d-11ec-90ce-5a00e3ca956d服务
2022-05-23 14:17:00.813 | INFO     | __main__:on_exit:43 - 服务注销成功
