2022-05-23 13:51:59.133 | INFO     | __main__:server:72 - 启动服务：192.168.23.1:65042
2022-05-23 13:51:59.141 | INFO     | __main__:server:75 - 服务注册开始
2022-05-23 13:51:59.327 | INFO     | __main__:server:82 - 服务注册成功
2022-05-23 13:52:01.859 | ERROR    | grpc._server:_call_behavior:443 - An error has been caught in function '_call_behavior', process 'MainProcess' (3804), thread 'ThreadPoolExecutor-0_0' (11128):
Traceback (most recent call last):

  File "C:\Users\admin\AppData\Local\Programs\Python\Python37\lib\threading.py", line 890, in _bootstrap
    self._bootstrap_inner()
    │    └ <function Thread._bootstrap_inner at 0x0000020EF31DFAF8>
    └ <Thread(ThreadPoolExecutor-0_0, started daemon 11128)>

  File "C:\Users\admin\AppData\Local\Programs\Python\Python37\lib\threading.py", line 926, in _bootstrap_inner
    self.run()
    │    └ <function Thread.run at 0x0000020EF31DF8B8>
    └ <Thread(ThreadPoolExecutor-0_0, started daemon 11128)>

  File "C:\Users\admin\AppData\Local\Programs\Python\Python37\lib\threading.py", line 870, in run
    self._target(*self._args, **self._kwargs)
    │    │        │    │        │    └ {}
    │    │        │    │        └ <Thread(ThreadPoolExecutor-0_0, started daemon 11128)>
    │    │        │    └ (<weakref at 0x0000020EF5C4EC28; to 'ThreadPoolExecutor' at 0x0000020EF5AE0A88>, <_queue.SimpleQueue object at 0x0000020EF5AD...
    │    │        └ <Thread(ThreadPoolExecutor-0_0, started daemon 11128)>
    │    └ <function _worker at 0x0000020EF5AE3828>
    └ <Thread(ThreadPoolExecutor-0_0, started daemon 11128)>

  File "C:\Users\admin\AppData\Local\Programs\Python\Python37\lib\concurrent\futures\thread.py", line 80, in _worker
    work_item.run()
    │         └ <function _WorkItem.run at 0x0000020EF5AE3948>
    └ <concurrent.futures.thread._WorkItem object at 0x0000020EF5C46C48>

  File "C:\Users\admin\AppData\Local\Programs\Python\Python37\lib\concurrent\futures\thread.py", line 57, in run
    result = self.fn(*self.args, **self.kwargs)
             │    │   │    │       │    └ {}
             │    │   │    │       └ <concurrent.futures.thread._WorkItem object at 0x0000020EF5C46C48>
             │    │   │    └ [<grpc._cython.cygrpc.RequestCallEvent object at 0x0000020EF5C4E818>, <grpc._server._RPCState object at 0x0000020EF5C3DE48>, ...
             │    │   └ <concurrent.futures.thread._WorkItem object at 0x0000020EF5C46C48>
             │    └ <function _unary_response_in_pool at 0x0000020EF5B10EE8>
             └ <concurrent.futures.thread._WorkItem object at 0x0000020EF5C46C48>

  File "D:\virtual-environment\py3.7\lib\site-packages\grpc\_server.py", line 561, in _unary_response_in_pool
    argument, request_deserializer)
    │         └ <built-in method FromString of GeneratedProtocolMessageType object at 0x0000020EF4EF19E8>
    └

> File "D:\virtual-environment\py3.7\lib\site-packages\grpc\_server.py", line 443, in _call_behavior
    response_or_iterator = behavior(argument, context)
                           │        │         └ <grpc._server._Context object at 0x0000020EF5C46408>
                           │        └ 
                           └ <bound method GoodsServicer.CategoryBrandList of <goods_srv.handler.goods.GoodsServicer object at 0x0000020EF5AE0E48>>

  File "D:\PythonProjects\shop\goods_srv\handler\goods.py", line 532, in CategoryBrandList
    category_brand_rsp.category.parentCategory = category_brand.category_id.parent_category_id
    │                  │                         │              └ <peewee.ForeignKeyAccessor object at 0x0000020EF57E6D88>
    │                  │                         └ <GoodsCategoryBrand: 12>
    │                  └ <field property 'CategoryBrandResponse.category'>
    └ id: 12
      brand {
        id: 628
        name: "\346\266\265\346\236\234"
        logo: "https://img30.360buyimg.com/popshop/jfs/t1/10755/20/8366...

TypeError: <Category: 135200> has type Category, but expected one of: int, long
2022-05-23 13:53:51.870 | INFO     | __main__:on_exit:41 - 注销75e3867a-da5c-11ec-a492-5a00e3ca956d服务
2022-05-23 13:53:51.968 | INFO     | __main__:on_exit:43 - 服务注销成功
