2022-05-23 14:17:12.403 | INFO     | __main__:server:72 - 启动服务：192.168.23.1:52518
2022-05-23 14:17:12.411 | INFO     | __main__:server:75 - 服务注册开始
2022-05-23 14:17:12.513 | INFO     | __main__:server:82 - 服务注册成功
2022-05-23 14:17:14.449 | ERROR    | grpc._server:_call_behavior:443 - An error has been caught in function '_call_behavior', process 'MainProcess' (1236), thread 'ThreadPoolExecutor-0_0' (2860):
Traceback (most recent call last):

  File "C:\Users\admin\AppData\Local\Programs\Python\Python37\lib\threading.py", line 890, in _bootstrap
    self._bootstrap_inner()
    │    └ <function Thread._bootstrap_inner at 0x000002818E55FAF8>
    └ <Thread(ThreadPoolExecutor-0_0, started daemon 2860)>

  File "C:\Users\admin\AppData\Local\Programs\Python\Python37\lib\threading.py", line 926, in _bootstrap_inner
    self.run()
    │    └ <function Thread.run at 0x000002818E55F8B8>
    └ <Thread(ThreadPoolExecutor-0_0, started daemon 2860)>

  File "C:\Users\admin\AppData\Local\Programs\Python\Python37\lib\threading.py", line 870, in run
    self._target(*self._args, **self._kwargs)
    │    │        │    │        │    └ {}
    │    │        │    │        └ <Thread(ThreadPoolExecutor-0_0, started daemon 2860)>
    │    │        │    └ (<weakref at 0x00000281911CFDB8; to 'ThreadPoolExecutor' at 0x00000281910468C8>, <_queue.SimpleQueue object at 0x000002819105...
    │    │        └ <Thread(ThreadPoolExecutor-0_0, started daemon 2860)>
    │    └ <function _worker at 0x0000028191063828>
    └ <Thread(ThreadPoolExecutor-0_0, started daemon 2860)>

  File "C:\Users\admin\AppData\Local\Programs\Python\Python37\lib\concurrent\futures\thread.py", line 80, in _worker
    work_item.run()
    │         └ <function _WorkItem.run at 0x0000028191063948>
    └ <concurrent.futures.thread._WorkItem object at 0x00000281911BDDC8>

  File "C:\Users\admin\AppData\Local\Programs\Python\Python37\lib\concurrent\futures\thread.py", line 57, in run
    result = self.fn(*self.args, **self.kwargs)
             │    │   │    │       │    └ {}
             │    │   │    │       └ <concurrent.futures.thread._WorkItem object at 0x00000281911BDDC8>
             │    │   │    └ [<grpc._cython.cygrpc.RequestCallEvent object at 0x00000281911CF9A8>, <grpc._server._RPCState object at 0x00000281911A9E88>, ...
             │    │   └ <concurrent.futures.thread._WorkItem object at 0x00000281911BDDC8>
             │    └ <function _unary_response_in_pool at 0x0000028191096048>
             └ <concurrent.futures.thread._WorkItem object at 0x00000281911BDDC8>

  File "D:\virtual-environment\py3.7\lib\site-packages\grpc\_server.py", line 561, in _unary_response_in_pool
    argument, request_deserializer)
    │         └ <built-in method FromString of GeneratedProtocolMessageType object at 0x000002818E771088>
    └ id: 136678

> File "D:\virtual-environment\py3.7\lib\site-packages\grpc\_server.py", line 443, in _call_behavior
    response_or_iterator = behavior(argument, context)
                           │        │         └ <grpc._server._Context object at 0x00000281911C8A88>
                           │        └ id: 136678
                           │          
                           └ <bound method GoodsServicer.GetCategoryBrandList of <goods_srv.handler.goods.GoodsServicer object at 0x0000028191060B08>>

  File "D:\PythonProjects\shop\goods_srv\handler\goods.py", line 549, in GetCategoryBrandList
    brand_rsp.id = category_brand.brand.id
    │         │    └ <GoodsCategoryBrand: 12>
    │         └ <field property 'BrandInfoResponse.id'>
    └

AttributeError: 'GoodsCategoryBrand' object has no attribute 'brand'
2022-05-23 14:19:31.324 | INFO     | __main__:on_exit:41 - 注销fbde31e4-da5f-11ec-a803-5a00e3ca956d服务
2022-05-23 14:19:31.335 | INFO     | __main__:on_exit:43 - 服务注销成功
