2022-04-26 14:43:34.398 | INFO     | __main__:server:72 - 启动服务：192.168.23.1:61899
2022-04-26 14:43:34.402 | INFO     | __main__:server:75 - 服务注册开始
2022-04-26 14:43:34.458 | INFO     | __main__:server:82 - 服务注册成功
2022-04-26 14:44:45.024 | ERROR    | grpc._server:_call_behavior:443 - An error has been caught in function '_call_behavior', process 'MainProcess' (3472), thread 'ThreadPoolExecutor-0_9' (4420):
Traceback (most recent call last):

  File "C:\Users\admin\AppData\Local\Programs\Python\Python37\lib\threading.py", line 890, in _bootstrap
    self._bootstrap_inner()
    │    └ <function Thread._bootstrap_inner at 0x000002A9D2500798>
    └ <Thread(ThreadPoolExecutor-0_9, started daemon 4420)>

  File "C:\Users\admin\AppData\Local\Programs\Python\Python37\lib\threading.py", line 926, in _bootstrap_inner
    self.run()
    │    └ <function Thread.run at 0x000002A9D2500558>
    └ <Thread(ThreadPoolExecutor-0_9, started daemon 4420)>

  File "C:\Users\admin\AppData\Local\Programs\Python\Python37\lib\threading.py", line 870, in run
    self._target(*self._args, **self._kwargs)
    │    │        │    │        │    └ {}
    │    │        │    │        └ <Thread(ThreadPoolExecutor-0_9, started daemon 4420)>
    │    │        │    └ (<weakref at 0x000002A9EE49D2C8; to 'ThreadPoolExecutor' at 0x000002A9EE315088>, <_queue.SimpleQueue object at 0x000002A9EE31...
    │    │        └ <Thread(ThreadPoolExecutor-0_9, started daemon 4420)>
    │    └ <function _worker at 0x000002A9EE31DAF8>
    └ <Thread(ThreadPoolExecutor-0_9, started daemon 4420)>

  File "C:\Users\admin\AppData\Local\Programs\Python\Python37\lib\concurrent\futures\thread.py", line 80, in _worker
    work_item.run()
    │         └ <function _WorkItem.run at 0x000002A9EE31DC18>
    └ <concurrent.futures.thread._WorkItem object at 0x000002A9EE49B808>

  File "C:\Users\admin\AppData\Local\Programs\Python\Python37\lib\concurrent\futures\thread.py", line 57, in run
    result = self.fn(*self.args, **self.kwargs)
             │    │   │    │       │    └ {}
             │    │   │    │       └ <concurrent.futures.thread._WorkItem object at 0x000002A9EE49B808>
             │    │   │    └ [<grpc._cython.cygrpc.RequestCallEvent object at 0x000002A9EE49DA48>, <grpc._server._RPCState object at 0x000002A9EE49B8C8>, ...
             │    │   └ <concurrent.futures.thread._WorkItem object at 0x000002A9EE49B808>
             │    └ <function _unary_response_in_pool at 0x000002A9EE34C288>
             └ <concurrent.futures.thread._WorkItem object at 0x000002A9EE49B808>

  File "D:\virtual-environment\py3.7\lib\site-packages\grpc\_server.py", line 561, in _unary_response_in_pool
    argument, request_deserializer)
    │         └ <built-in method FromString of GeneratedProtocolMessageType object at 0x000002A9ECFE4418>
    └ id: 421
      id: 422

> File "D:\virtual-environment\py3.7\lib\site-packages\grpc\_server.py", line 443, in _call_behavior
    response_or_iterator = behavior(argument, context)
                           │        │         └ <grpc._server._Context object at 0x000002A9EE49BCC8>
                           │        └ id: 421
                           │          id: 422
                           │          
                           └ <bound method GoodsServicer.BatchGetGoods of <goods_srv.handler.goods.GoodsServicer object at 0x000002A9EE3230C8>>

  File "D:\PythonProjects\shop\goods_srv\handler\goods.py", line 99, in BatchGetGoods
    goods = Goods.where(Goods.id.in_(request.id))
            │           │     │      │       └ <field property 'BatchGoodsIdInfo.id'>
            │           │     │      └ id: 421
            │           │     │        id: 422
            │           │     │        
            │           │     └ <peewee.FieldAccessor object at 0x000002A9EDF20888>
            │           └ <Model: Goods>
            └ <Model: Goods>

AttributeError: type object 'Goods' has no attribute 'where'
2022-04-26 14:44:50.316 | ERROR    | grpc._server:_call_behavior:443 - An error has been caught in function '_call_behavior', process 'MainProcess' (3472), thread 'ThreadPoolExecutor-0_1' (13440):
Traceback (most recent call last):

  File "C:\Users\admin\AppData\Local\Programs\Python\Python37\lib\threading.py", line 890, in _bootstrap
    self._bootstrap_inner()
    │    └ <function Thread._bootstrap_inner at 0x000002A9D2500798>
    └ <Thread(ThreadPoolExecutor-0_1, started daemon 13440)>

  File "C:\Users\admin\AppData\Local\Programs\Python\Python37\lib\threading.py", line 926, in _bootstrap_inner
    self.run()
    │    └ <function Thread.run at 0x000002A9D2500558>
    └ <Thread(ThreadPoolExecutor-0_1, started daemon 13440)>

  File "C:\Users\admin\AppData\Local\Programs\Python\Python37\lib\threading.py", line 870, in run
    self._target(*self._args, **self._kwargs)
    │    │        │    │        │    └ {}
    │    │        │    │        └ <Thread(ThreadPoolExecutor-0_1, started daemon 13440)>
    │    │        │    └ (<weakref at 0x000002A9EE4819F8; to 'ThreadPoolExecutor' at 0x000002A9EE315088>, <_queue.SimpleQueue object at 0x000002A9EE31...
    │    │        └ <Thread(ThreadPoolExecutor-0_1, started daemon 13440)>
    │    └ <function _worker at 0x000002A9EE31DAF8>
    └ <Thread(ThreadPoolExecutor-0_1, started daemon 13440)>

  File "C:\Users\admin\AppData\Local\Programs\Python\Python37\lib\concurrent\futures\thread.py", line 80, in _worker
    work_item.run()
    │         └ <function _WorkItem.run at 0x000002A9EE31DC18>
    └ <concurrent.futures.thread._WorkItem object at 0x000002A9EE49BCC8>

  File "C:\Users\admin\AppData\Local\Programs\Python\Python37\lib\concurrent\futures\thread.py", line 57, in run
    result = self.fn(*self.args, **self.kwargs)
             │    │   │    │       │    └ {}
             │    │   │    │       └ <concurrent.futures.thread._WorkItem object at 0x000002A9EE49BCC8>
             │    │   │    └ [<grpc._cython.cygrpc.RequestCallEvent object at 0x000002A9EE49DCC8>, <grpc._server._RPCState object at 0x000002A9EE49BD88>, ...
             │    │   └ <concurrent.futures.thread._WorkItem object at 0x000002A9EE49BCC8>
             │    └ <function _unary_response_in_pool at 0x000002A9EE34C288>
             └ <concurrent.futures.thread._WorkItem object at 0x000002A9EE49BCC8>

  File "D:\virtual-environment\py3.7\lib\site-packages\grpc\_server.py", line 561, in _unary_response_in_pool
    argument, request_deserializer)
    │         └ <built-in method FromString of GeneratedProtocolMessageType object at 0x000002A9ECFE4418>
    └ id: 421
      id: 422

> File "D:\virtual-environment\py3.7\lib\site-packages\grpc\_server.py", line 443, in _call_behavior
    response_or_iterator = behavior(argument, context)
                           │        │         └ <grpc._server._Context object at 0x000002A9EE5CA888>
                           │        └ id: 421
                           │          id: 422
                           │          
                           └ <bound method GoodsServicer.BatchGetGoods of <goods_srv.handler.goods.GoodsServicer object at 0x000002A9EE3230C8>>

  File "D:\PythonProjects\shop\goods_srv\handler\goods.py", line 99, in BatchGetGoods
    goods = Goods.where(Goods.id.in_(request.id))
            │           │     │      │       └ <field property 'BatchGoodsIdInfo.id'>
            │           │     │      └ id: 421
            │           │     │        id: 422
            │           │     │        
            │           │     └ <peewee.FieldAccessor object at 0x000002A9EDF20888>
            │           └ <Model: Goods>
            └ <Model: Goods>

AttributeError: type object 'Goods' has no attribute 'where'
2022-04-26 14:45:32.131 | ERROR    | grpc._server:_call_behavior:443 - An error has been caught in function '_call_behavior', process 'MainProcess' (3472), thread 'ThreadPoolExecutor-0_0' (1464):
Traceback (most recent call last):

  File "C:\Users\admin\AppData\Local\Programs\Python\Python37\lib\threading.py", line 890, in _bootstrap
    self._bootstrap_inner()
    │    └ <function Thread._bootstrap_inner at 0x000002A9D2500798>
    └ <Thread(ThreadPoolExecutor-0_0, started daemon 1464)>

  File "C:\Users\admin\AppData\Local\Programs\Python\Python37\lib\threading.py", line 926, in _bootstrap_inner
    self.run()
    │    └ <function Thread.run at 0x000002A9D2500558>
    └ <Thread(ThreadPoolExecutor-0_0, started daemon 1464)>

  File "C:\Users\admin\AppData\Local\Programs\Python\Python37\lib\threading.py", line 870, in run
    self._target(*self._args, **self._kwargs)
    │    │        │    │        │    └ {}
    │    │        │    │        └ <Thread(ThreadPoolExecutor-0_0, started daemon 1464)>
    │    │        │    └ (<weakref at 0x000002A9EE481638; to 'ThreadPoolExecutor' at 0x000002A9EE315088>, <_queue.SimpleQueue object at 0x000002A9EE31...
    │    │        └ <Thread(ThreadPoolExecutor-0_0, started daemon 1464)>
    │    └ <function _worker at 0x000002A9EE31DAF8>
    └ <Thread(ThreadPoolExecutor-0_0, started daemon 1464)>

  File "C:\Users\admin\AppData\Local\Programs\Python\Python37\lib\concurrent\futures\thread.py", line 80, in _worker
    work_item.run()
    │         └ <function _WorkItem.run at 0x000002A9EE31DC18>
    └ <concurrent.futures.thread._WorkItem object at 0x000002A9EE485048>

  File "C:\Users\admin\AppData\Local\Programs\Python\Python37\lib\concurrent\futures\thread.py", line 57, in run
    result = self.fn(*self.args, **self.kwargs)
             │    │   │    │       │    └ {}
             │    │   │    │       └ <concurrent.futures.thread._WorkItem object at 0x000002A9EE485048>
             │    │   │    └ [<grpc._cython.cygrpc.RequestCallEvent object at 0x000002A9EE5D6098>, <grpc._server._RPCState object at 0x000002A9EE4854C8>, ...
             │    │   └ <concurrent.futures.thread._WorkItem object at 0x000002A9EE485048>
             │    └ <function _unary_response_in_pool at 0x000002A9EE34C288>
             └ <concurrent.futures.thread._WorkItem object at 0x000002A9EE485048>

  File "D:\virtual-environment\py3.7\lib\site-packages\grpc\_server.py", line 561, in _unary_response_in_pool
    argument, request_deserializer)
    │         └ <built-in method FromString of GeneratedProtocolMessageType object at 0x000002A9ECFE4418>
    └ id: 421
      id: 424

> File "D:\virtual-environment\py3.7\lib\site-packages\grpc\_server.py", line 443, in _call_behavior
    response_or_iterator = behavior(argument, context)
                           │        │         └ <grpc._server._Context object at 0x000002A9EE36E188>
                           │        └ id: 421
                           │          id: 424
                           │          
                           └ <bound method GoodsServicer.BatchGetGoods of <goods_srv.handler.goods.GoodsServicer object at 0x000002A9EE3230C8>>

  File "D:\PythonProjects\shop\goods_srv\handler\goods.py", line 99, in BatchGetGoods
    goods = Goods.where(Goods.id.in_(request.id))
            │           │     │      │       └ <field property 'BatchGoodsIdInfo.id'>
            │           │     │      └ id: 421
            │           │     │        id: 424
            │           │     │        
            │           │     └ <peewee.FieldAccessor object at 0x000002A9EDF20888>
            │           └ <Model: Goods>
            └ <Model: Goods>

AttributeError: type object 'Goods' has no attribute 'where'
