2022-05-11 16:22:24.002 | INFO     | __main__:server:72 - 启动服务：192.168.23.1:58519
2022-05-11 16:22:24.014 | INFO     | __main__:server:75 - 服务注册开始
2022-05-11 16:22:24.302 | INFO     | __main__:server:82 - 服务注册成功
2022-05-11 16:37:45.767 | ERROR    | grpc._server:_call_behavior:443 - An error has been caught in function '_call_behavior', process 'MainProcess' (3580), thread 'ThreadPoolExecutor-0_7' (7388):
Traceback (most recent call last):

  File "C:\Users\admin\AppData\Local\Programs\Python\Python37\lib\threading.py", line 890, in _bootstrap
    self._bootstrap_inner()
    │    └ <function Thread._bootstrap_inner at 0x0000021017C7FAF8>
    └ <Thread(ThreadPoolExecutor-0_7, started daemon 7388)>

  File "C:\Users\admin\AppData\Local\Programs\Python\Python37\lib\threading.py", line 926, in _bootstrap_inner
    self.run()
    │    └ <function Thread.run at 0x0000021017C7F8B8>
    └ <Thread(ThreadPoolExecutor-0_7, started daemon 7388)>

  File "C:\Users\admin\AppData\Local\Programs\Python\Python37\lib\threading.py", line 870, in run
    self._target(*self._args, **self._kwargs)
    │    │        │    │        │    └ {}
    │    │        │    │        └ <Thread(ThreadPoolExecutor-0_7, started daemon 7388)>
    │    │        │    └ (<weakref at 0x000002101AC2C728; to 'ThreadPoolExecutor' at 0x000002101AAADFC8>, <_queue.SimpleQueue object at 0x000002101AAA...
    │    │        └ <Thread(ThreadPoolExecutor-0_7, started daemon 7388)>
    │    └ <function _worker at 0x000002101AAB1828>
    └ <Thread(ThreadPoolExecutor-0_7, started daemon 7388)>

  File "C:\Users\admin\AppData\Local\Programs\Python\Python37\lib\concurrent\futures\thread.py", line 80, in _worker
    work_item.run()
    │         └ <function _WorkItem.run at 0x000002101AAB1948>
    └ <concurrent.futures.thread._WorkItem object at 0x000002101AE9DC48>

  File "C:\Users\admin\AppData\Local\Programs\Python\Python37\lib\concurrent\futures\thread.py", line 57, in run
    result = self.fn(*self.args, **self.kwargs)
             │    │   │    │       │    └ {}
             │    │   │    │       └ <concurrent.futures.thread._WorkItem object at 0x000002101AE9DC48>
             │    │   │    └ [<grpc._cython.cygrpc.RequestCallEvent object at 0x000002101AEA2E08>, <grpc._server._RPCState object at 0x000002101AE9D8C8>, ...
             │    │   └ <concurrent.futures.thread._WorkItem object at 0x000002101AE9DC48>
             │    └ <function _unary_response_in_pool at 0x000002101AADFF78>
             └ <concurrent.futures.thread._WorkItem object at 0x000002101AE9DC48>

  File "D:\virtual-environment\py3.7\lib\site-packages\grpc\_server.py", line 561, in _unary_response_in_pool
    argument, request_deserializer)
    │         └ <built-in method FromString of GeneratedProtocolMessageType object at 0x0000021017E411D8>
    └ id: 2

> File "D:\virtual-environment\py3.7\lib\site-packages\grpc\_server.py", line 443, in _call_behavior
    response_or_iterator = behavior(argument, context)
                           │        │         └ <grpc._server._Context object at 0x000002101AE9D108>
                           │        └ id: 2
                           │          
                           └ <bound method OrderServicer.CartItemList of <order_srv.handler.order.OrderServicer object at 0x000002101AAB5048>>

  File "D:\PythonProjects\shop\order_srv\handler\order.py", line 28, in CartItemList
    item_rsp.userID = item.user
    │                 │    └ <peewee.FieldAccessor object at 0x000002101A6A6E48>
    │                 └ <ShoppingCart: 2>
    └ id: 2

AttributeError: 'ShopCartInfoResponse' object has no attribute 'userID'
2022-05-11 16:41:52.839 | INFO     | __main__:on_exit:41 - 注销7c2c5334-d103-11ec-a568-5800e3ca956e服务
2022-05-11 16:41:52.887 | INFO     | __main__:on_exit:43 - 服务注销成功
