2022-05-11 16:42:01.184 | INFO     | __main__:server:72 - 启动服务：192.168.23.1:59615
2022-05-11 16:42:01.186 | INFO     | __main__:server:75 - 服务注册开始
2022-05-11 16:42:01.216 | INFO     | __main__:server:82 - 服务注册成功
2022-05-11 16:43:03.367 | ERROR    | grpc._server:_call_behavior:443 - An error has been caught in function '_call_behavior', process 'MainProcess' (17820), thread 'ThreadPoolExecutor-0_5' (16916):
Traceback (most recent call last):

  File "C:\Users\admin\AppData\Local\Programs\Python\Python37\lib\threading.py", line 890, in _bootstrap
    self._bootstrap_inner()
    │    └ <function Thread._bootstrap_inner at 0x000002BC178EFAF8>
    └ <Thread(ThreadPoolExecutor-0_5, started daemon 16916)>

  File "C:\Users\admin\AppData\Local\Programs\Python\Python37\lib\threading.py", line 926, in _bootstrap_inner
    self.run()
    │    └ <function Thread.run at 0x000002BC178EF8B8>
    └ <Thread(ThreadPoolExecutor-0_5, started daemon 16916)>

  File "C:\Users\admin\AppData\Local\Programs\Python\Python37\lib\threading.py", line 870, in run
    self._target(*self._args, **self._kwargs)
    │    │        │    │        │    └ {}
    │    │        │    │        └ <Thread(ThreadPoolExecutor-0_5, started daemon 16916)>
    │    │        │    └ (<weakref at 0x000002BC1A8B30E8; to 'ThreadPoolExecutor' at 0x000002BC1A715F88>, <_queue.SimpleQueue object at 0x000002BC1A71...
    │    │        └ <Thread(ThreadPoolExecutor-0_5, started daemon 16916)>
    │    └ <function _worker at 0x000002BC1A721828>
    └ <Thread(ThreadPoolExecutor-0_5, started daemon 16916)>

  File "C:\Users\admin\AppData\Local\Programs\Python\Python37\lib\concurrent\futures\thread.py", line 80, in _worker
    work_item.run()
    │         └ <function _WorkItem.run at 0x000002BC1A721948>
    └ <concurrent.futures.thread._WorkItem object at 0x000002BC1A8BA308>

  File "C:\Users\admin\AppData\Local\Programs\Python\Python37\lib\concurrent\futures\thread.py", line 57, in run
    result = self.fn(*self.args, **self.kwargs)
             │    │   │    │       │    └ {}
             │    │   │    │       └ <concurrent.futures.thread._WorkItem object at 0x000002BC1A8BA308>
             │    │   │    └ [<grpc._cython.cygrpc.RequestCallEvent object at 0x000002BC1A8B7D18>, <grpc._server._RPCState object at 0x000002BC1A8BA208>, ...
             │    │   └ <concurrent.futures.thread._WorkItem object at 0x000002BC1A8BA308>
             │    └ <function _unary_response_in_pool at 0x000002BC1A74FF78>
             └ <concurrent.futures.thread._WorkItem object at 0x000002BC1A8BA308>

  File "D:\virtual-environment\py3.7\lib\site-packages\grpc\_server.py", line 561, in _unary_response_in_pool
    argument, request_deserializer)
    │         └ <built-in method FromString of GeneratedProtocolMessageType object at 0x000002BC17A9BEC8>
    └ id: 1

> File "D:\virtual-environment\py3.7\lib\site-packages\grpc\_server.py", line 443, in _call_behavior
    response_or_iterator = behavior(argument, context)
                           │        │         └ <grpc._server._Context object at 0x000002BC1A8BA448>
                           │        └ id: 1
                           │          
                           └ <bound method OrderServicer.CartItemList of <order_srv.handler.order.OrderServicer object at 0x000002BC1A725248>>

  File "D:\PythonProjects\shop\order_srv\handler\order.py", line 28, in CartItemList
    item_rsp.userID = item.user
    │                 │    └ <peewee.FieldAccessor object at 0x000002BC1A322048>
    │                 └ <ShoppingCart: 1>
    └ id: 1

AttributeError: 'ShopCartInfoResponse' object has no attribute 'userID'
2022-05-11 16:46:02.213 | INFO     | __main__:on_exit:41 - 注销39d3c5d2-d106-11ec-a694-5800e3ca956e服务
2022-05-11 16:46:02.222 | INFO     | __main__:on_exit:43 - 服务注销成功
