2022-05-12 19:50:52.242 | INFO     | __main__:server:72 - 启动服务：192.168.23.1:51638
2022-05-12 19:50:52.247 | INFO     | __main__:server:75 - 服务注册开始
2022-05-12 19:50:52.286 | INFO     | __main__:server:82 - 服务注册成功
2022-05-12 19:55:40.524 | ERROR    | grpc._server:_call_behavior:443 - An error has been caught in function '_call_behavior', process 'MainProcess' (18788), thread 'ThreadPoolExecutor-0_6' (20300):
Traceback (most recent call last):

  File "C:\Users\admin\AppData\Local\Programs\Python\Python37\lib\threading.py", line 890, in _bootstrap
    self._bootstrap_inner()
    │    └ <function Thread._bootstrap_inner at 0x0000024263DDFAF8>
    └ <Thread(ThreadPoolExecutor-0_6, started daemon 20300)>

  File "C:\Users\admin\AppData\Local\Programs\Python\Python37\lib\threading.py", line 926, in _bootstrap_inner
    self.run()
    │    └ <function Thread.run at 0x0000024263DDF8B8>
    └ <Thread(ThreadPoolExecutor-0_6, started daemon 20300)>

  File "C:\Users\admin\AppData\Local\Programs\Python\Python37\lib\threading.py", line 870, in run
    self._target(*self._args, **self._kwargs)
    │    │        │    │        │    └ {}
    │    │        │    │        └ <Thread(ThreadPoolExecutor-0_6, started daemon 20300)>
    │    │        │    └ (<weakref at 0x0000024266B7D1D8; to 'ThreadPoolExecutor' at 0x00000242669F5F48>, <_queue.SimpleQueue object at 0x00000242669F...
    │    │        └ <Thread(ThreadPoolExecutor-0_6, started daemon 20300)>
    │    └ <function _worker at 0x0000024266A03798>
    └ <Thread(ThreadPoolExecutor-0_6, started daemon 20300)>

  File "C:\Users\admin\AppData\Local\Programs\Python\Python37\lib\concurrent\futures\thread.py", line 80, in _worker
    work_item.run()
    │         └ <function _WorkItem.run at 0x0000024266A038B8>
    └ <concurrent.futures.thread._WorkItem object at 0x0000024266B88148>

  File "C:\Users\admin\AppData\Local\Programs\Python\Python37\lib\concurrent\futures\thread.py", line 57, in run
    result = self.fn(*self.args, **self.kwargs)
             │    │   │    │       │    └ {}
             │    │   │    │       └ <concurrent.futures.thread._WorkItem object at 0x0000024266B88148>
             │    │   │    └ [<grpc._cython.cygrpc.RequestCallEvent object at 0x0000024266B84E58>, <grpc._server._RPCState object at 0x0000024266B87FC8>, ...
             │    │   └ <concurrent.futures.thread._WorkItem object at 0x0000024266B88148>
             │    └ <function _unary_response_in_pool at 0x0000024266A2FEE8>
             └ <concurrent.futures.thread._WorkItem object at 0x0000024266B88148>

  File "D:\virtual-environment\py3.7\lib\site-packages\grpc\_server.py", line 561, in _unary_response_in_pool
    argument, request_deserializer)
    │         └ <built-in method FromString of GeneratedProtocolMessageType object at 0x0000024263D1A5F8>
    └ id: 2

> File "D:\virtual-environment\py3.7\lib\site-packages\grpc\_server.py", line 443, in _call_behavior
    response_or_iterator = behavior(argument, context)
                           │        │         └ <grpc._server._Context object at 0x0000024266B88188>
                           │        └ id: 2
                           │          
                           └ <bound method OrderServicer.OrderDetail of <order_srv.handler.order.OrderServicer object at 0x0000024266A06348>>

  File "D:\PythonProjects\shop\order_srv\handler\order.py", line 241, in OrderDetail
    order_goods_rsp.goodsPrice = float(order_good.goods_price)
    │               │                  │          └ <peewee.FieldAccessor object at 0x0000024266606808>
    │               │                  └ <OrderGoods: 2>
    │               └ <field property 'OrderItemResponse.goodsPrice'>
    └ goodsId: 421
      goodsName: "\347\203\237\345\217\260\347\272\242\345\257\214\345\243\253\350\213\271\346\236\23412\344\270\252 \...

TypeError: 44.9 has type float, but expected one of: bytes, unicode
2022-05-12 19:56:34.116 | ERROR    | grpc._server:_call_behavior:443 - An error has been caught in function '_call_behavior', process 'MainProcess' (18788), thread 'ThreadPoolExecutor-0_4' (19640):
Traceback (most recent call last):

  File "C:\Users\admin\AppData\Local\Programs\Python\Python37\lib\threading.py", line 890, in _bootstrap
    self._bootstrap_inner()
    │    └ <function Thread._bootstrap_inner at 0x0000024263DDFAF8>
    └ <Thread(ThreadPoolExecutor-0_4, started daemon 19640)>

  File "C:\Users\admin\AppData\Local\Programs\Python\Python37\lib\threading.py", line 926, in _bootstrap_inner
    self.run()
    │    └ <function Thread.run at 0x0000024263DDF8B8>
    └ <Thread(ThreadPoolExecutor-0_4, started daemon 19640)>

  File "C:\Users\admin\AppData\Local\Programs\Python\Python37\lib\threading.py", line 870, in run
    self._target(*self._args, **self._kwargs)
    │    │        │    │        │    └ {}
    │    │        │    │        └ <Thread(ThreadPoolExecutor-0_4, started daemon 19640)>
    │    │        │    └ (<weakref at 0x0000024266B79318; to 'ThreadPoolExecutor' at 0x00000242669F5F48>, <_queue.SimpleQueue object at 0x00000242669F...
    │    │        └ <Thread(ThreadPoolExecutor-0_4, started daemon 19640)>
    │    └ <function _worker at 0x0000024266A03798>
    └ <Thread(ThreadPoolExecutor-0_4, started daemon 19640)>

  File "C:\Users\admin\AppData\Local\Programs\Python\Python37\lib\concurrent\futures\thread.py", line 80, in _worker
    work_item.run()
    │         └ <function _WorkItem.run at 0x0000024266A038B8>
    └ <concurrent.futures.thread._WorkItem object at 0x0000024266E3AA48>

  File "C:\Users\admin\AppData\Local\Programs\Python\Python37\lib\concurrent\futures\thread.py", line 57, in run
    result = self.fn(*self.args, **self.kwargs)
             │    │   │    │       │    └ {}
             │    │   │    │       └ <concurrent.futures.thread._WorkItem object at 0x0000024266E3AA48>
             │    │   │    └ [<grpc._cython.cygrpc.RequestCallEvent object at 0x0000024266DE3778>, <grpc._server._RPCState object at 0x0000024266E3ACC8>, ...
             │    │   └ <concurrent.futures.thread._WorkItem object at 0x0000024266E3AA48>
             │    └ <function _unary_response_in_pool at 0x0000024266A2FEE8>
             └ <concurrent.futures.thread._WorkItem object at 0x0000024266E3AA48>

  File "D:\virtual-environment\py3.7\lib\site-packages\grpc\_server.py", line 561, in _unary_response_in_pool
    argument, request_deserializer)
    │         └ <built-in method FromString of GeneratedProtocolMessageType object at 0x0000024263D1A5F8>
    └ id: 3

> File "D:\virtual-environment\py3.7\lib\site-packages\grpc\_server.py", line 443, in _call_behavior
    response_or_iterator = behavior(argument, context)
                           │        │         └ <grpc._server._Context object at 0x0000024266E3AAC8>
                           │        └ id: 3
                           │          
                           └ <bound method OrderServicer.OrderDetail of <order_srv.handler.order.OrderServicer object at 0x0000024266A06348>>

  File "D:\PythonProjects\shop\order_srv\handler\order.py", line 241, in OrderDetail
    order_goods_rsp.goodsPrice = float(order_good.goods_price)
    │               │                  │          └ <peewee.FieldAccessor object at 0x0000024266606808>
    │               │                  └ <OrderGoods: 3>
    │               └ <field property 'OrderItemResponse.goodsPrice'>
    └ goodsId: 421
      goodsName: "\347\203\237\345\217\260\347\272\242\345\257\214\345\243\253\350\213\271\346\236\23412\344\270\252 \...

TypeError: 44.9 has type float, but expected one of: bytes, unicode
2022-05-12 20:01:43.580 | INFO     | __main__:on_exit:41 - 注销c613f6cc-d1e9-11ec-90d8-5800e3ca956e服务
2022-05-12 20:01:43.707 | INFO     | __main__:on_exit:43 - 服务注销成功
