2022-05-12 15:49:12.498 | INFO     | __main__:server:72 - 启动服务：192.168.23.1:60559
2022-05-12 15:49:12.501 | INFO     | __main__:server:75 - 服务注册开始
2022-05-12 15:49:12.585 | INFO     | __main__:server:82 - 服务注册成功
2022-05-12 15:49:17.297 | ERROR    | grpc._server:_call_behavior:443 - An error has been caught in function '_call_behavior', process 'MainProcess' (12168), thread 'ThreadPoolExecutor-0_0' (19260):
Traceback (most recent call last):

  File "C:\Users\admin\AppData\Local\Programs\Python\Python37\lib\threading.py", line 890, in _bootstrap
    self._bootstrap_inner()
    │    └ <function Thread._bootstrap_inner at 0x0000022F07C8FAF8>
    └ <Thread(ThreadPoolExecutor-0_0, started daemon 19260)>

  File "C:\Users\admin\AppData\Local\Programs\Python\Python37\lib\threading.py", line 926, in _bootstrap_inner
    self.run()
    │    └ <function Thread.run at 0x0000022F07C8F8B8>
    └ <Thread(ThreadPoolExecutor-0_0, started daemon 19260)>

  File "C:\Users\admin\AppData\Local\Programs\Python\Python37\lib\threading.py", line 870, in run
    self._target(*self._args, **self._kwargs)
    │    │        │    │        │    └ {}
    │    │        │    │        └ <Thread(ThreadPoolExecutor-0_0, started daemon 19260)>
    │    │        │    └ (<weakref at 0x0000022F0AC2A818; to 'ThreadPoolExecutor' at 0x0000022F0AAA2288>, <_queue.SimpleQueue object at 0x0000022F0AAB...
    │    │        └ <Thread(ThreadPoolExecutor-0_0, started daemon 19260)>
    │    └ <function _worker at 0x0000022F0AABE678>
    └ <Thread(ThreadPoolExecutor-0_0, started daemon 19260)>

  File "C:\Users\admin\AppData\Local\Programs\Python\Python37\lib\concurrent\futures\thread.py", line 80, in _worker
    work_item.run()
    │         └ <function _WorkItem.run at 0x0000022F0AABE798>
    └ <concurrent.futures.thread._WorkItem object at 0x0000022F0AB0B188>

  File "C:\Users\admin\AppData\Local\Programs\Python\Python37\lib\concurrent\futures\thread.py", line 57, in run
    result = self.fn(*self.args, **self.kwargs)
             │    │   │    │       │    └ {}
             │    │   │    │       └ <concurrent.futures.thread._WorkItem object at 0x0000022F0AB0B188>
             │    │   │    └ [<grpc._cython.cygrpc.RequestCallEvent object at 0x0000022F0AC2A598>, <grpc._server._RPCState object at 0x0000022F0AAFAB88>, ...
             │    │   └ <concurrent.futures.thread._WorkItem object at 0x0000022F0AB0B188>
             │    └ <function _unary_response_in_pool at 0x0000022F0AAEFEE8>
             └ <concurrent.futures.thread._WorkItem object at 0x0000022F0AB0B188>

  File "D:\virtual-environment\py3.7\lib\site-packages\grpc\_server.py", line 561, in _unary_response_in_pool
    argument, request_deserializer)
    │         └ <built-in method FromString of GeneratedProtocolMessageType object at 0x0000022F07E7DA78>
    └ id: 2

> File "D:\virtual-environment\py3.7\lib\site-packages\grpc\_server.py", line 443, in _call_behavior
    response_or_iterator = behavior(argument, context)
                           │        │         └ <grpc._server._Context object at 0x0000022F0AB1BBC8>
                           │        └ id: 2
                           │          
                           └ <bound method OrderServicer.OrderDetail of <order_srv.handler.order.OrderServicer object at 0x0000022F0AAC5288>>

  File "D:\PythonProjects\shop\order_srv\handler\order.py", line 241, in OrderDetail
    order_goods_rsp.goodsPrice = float(order_good.goods_price)
    │               │                  │          └ <peewee.FieldAccessor object at 0x0000022F0A6C8588>
    │               │                  └ <OrderGoods: 2>
    │               └ <field property 'OrderItemResponse.goodsPrice'>
    └ goodsId: 421
      goodsName: "\347\203\237\345\217\260\347\272\242\345\257\214\345\243\253\350\213\271\346\236\23412\344\270\252 \...

TypeError: 44.9 has type float, but expected one of: bytes, unicode
2022-05-12 19:50:38.080 | INFO     | __main__:on_exit:41 - 注销038e6830-d1c8-11ec-92a4-5800e3ca956e服务
2022-05-12 19:50:38.241 | INFO     | __main__:on_exit:43 - 服务注销成功
