2022-05-12 11:03:32.936 | INFO     | __main__:server:72 - 启动服务：192.168.23.1:56186
2022-05-12 11:03:32.940 | INFO     | __main__:server:75 - 服务注册开始
2022-05-12 11:03:33.012 | INFO     | __main__:server:82 - 服务注册成功
2022-05-12 11:03:58.734 | ERROR    | grpc._server:_call_behavior:443 - An error has been caught in function '_call_behavior', process 'MainProcess' (8984), thread 'ThreadPoolExecutor-0_3' (8028):
Traceback (most recent call last):

  File "C:\Users\admin\AppData\Local\Programs\Python\Python37\lib\threading.py", line 890, in _bootstrap
    self._bootstrap_inner()
    │    └ <function Thread._bootstrap_inner at 0x000001C2D455FAF8>
    └ <Thread(ThreadPoolExecutor-0_3, started daemon 8028)>

  File "C:\Users\admin\AppData\Local\Programs\Python\Python37\lib\threading.py", line 926, in _bootstrap_inner
    self.run()
    │    └ <function Thread.run at 0x000001C2D455F8B8>
    └ <Thread(ThreadPoolExecutor-0_3, started daemon 8028)>

  File "C:\Users\admin\AppData\Local\Programs\Python\Python37\lib\threading.py", line 870, in run
    self._target(*self._args, **self._kwargs)
    │    │        │    │        │    └ {}
    │    │        │    │        └ <Thread(ThreadPoolExecutor-0_3, started daemon 8028)>
    │    │        │    └ (<weakref at 0x000001C2D75FCF98; to 'ThreadPoolExecutor' at 0x000001C2D738B1C8>, <_queue.SimpleQueue object at 0x000001C2D738...
    │    │        └ <Thread(ThreadPoolExecutor-0_3, started daemon 8028)>
    │    └ <function _worker at 0x000001C2D7392798>
    └ <Thread(ThreadPoolExecutor-0_3, started daemon 8028)>

  File "C:\Users\admin\AppData\Local\Programs\Python\Python37\lib\concurrent\futures\thread.py", line 80, in _worker
    work_item.run()
    │         └ <function _WorkItem.run at 0x000001C2D73928B8>
    └ <concurrent.futures.thread._WorkItem object at 0x000001C2D73E8548>

  File "C:\Users\admin\AppData\Local\Programs\Python\Python37\lib\concurrent\futures\thread.py", line 57, in run
    result = self.fn(*self.args, **self.kwargs)
             │    │   │    │       │    └ {}
             │    │   │    │       └ <concurrent.futures.thread._WorkItem object at 0x000001C2D73E8548>
             │    │   │    └ [<grpc._cython.cygrpc.RequestCallEvent object at 0x000001C2D75FC458>, <grpc._server._RPCState object at 0x000001C2D73E8488>, ...
             │    │   └ <concurrent.futures.thread._WorkItem object at 0x000001C2D73E8548>
             │    └ <function _unary_response_in_pool at 0x000001C2D73C0EE8>
             └ <concurrent.futures.thread._WorkItem object at 0x000001C2D73E8548>

  File "D:\virtual-environment\py3.7\lib\site-packages\grpc\_server.py", line 561, in _unary_response_in_pool
    argument, request_deserializer)
    │         └ <built-in method FromString of GeneratedProtocolMessageType object at 0x000001C2D47C8D08>
    └

> File "D:\virtual-environment\py3.7\lib\site-packages\grpc\_server.py", line 443, in _call_behavior
    response_or_iterator = behavior(argument, context)
                           │        │         └ <grpc._server._Context object at 0x000001C2D75FB3C8>
                           │        └ 
                           └ <bound method OrderServicer.OrderList of <order_srv.handler.order.OrderServicer object at 0x000001C2D7394488>>

  File "D:\PythonProjects\shop\order_srv\handler\order.py", line 208, in OrderList
    tmp_rsp.addTime = order.add_time.strftime('%Y-%m-%d %H:%M:%S')
    │                 │     └ <peewee.FieldAccessor object at 0x000001C2D6F94E08>
    │                 └ <OrderInfo: 3>
    └ id: 3
      orderSn: "20220510145248142"
      payType: "alipay"
      status: "paying"
      post: "\345\260\275\345\277\253\345\217\221\350\264\247...

AttributeError: 'OrderInfoResponse' object has no attribute 'addTime'
2022-05-12 11:05:00.540 | INFO     | __main__:on_exit:41 - 注销1b94f91e-d1a0-11ec-a2eb-5800e3ca956e服务
2022-05-12 11:05:00.567 | INFO     | __main__:on_exit:43 - 服务注销成功
