2022-05-20 13:03:56.096 | INFO     | __main__:server:71 - 启动服务：192.168.23.1:59110
2022-05-20 13:03:56.101 | INFO     | __main__:server:73 - 服务注册开始
2022-05-20 13:03:56.147 | INFO     | __main__:server:79 - 服务注册成功
2022-05-20 13:03:59.548 | ERROR    | grpc._server:_call_behavior:443 - An error has been caught in function '_call_behavior', process 'MainProcess' (11184), thread 'ThreadPoolExecutor-0_0' (15512):
Traceback (most recent call last):

  File "C:\Users\admin\AppData\Local\Programs\Python\Python37\lib\threading.py", line 890, in _bootstrap
    self._bootstrap_inner()
    │    └ <function Thread._bootstrap_inner at 0x00000230B691FAF8>
    └ <Thread(ThreadPoolExecutor-0_0, started daemon 15512)>

  File "C:\Users\admin\AppData\Local\Programs\Python\Python37\lib\threading.py", line 926, in _bootstrap_inner
    self.run()
    │    └ <function Thread.run at 0x00000230B691F8B8>
    └ <Thread(ThreadPoolExecutor-0_0, started daemon 15512)>

  File "C:\Users\admin\AppData\Local\Programs\Python\Python37\lib\threading.py", line 870, in run
    self._target(*self._args, **self._kwargs)
    │    │        │    │        │    └ {}
    │    │        │    │        └ <Thread(ThreadPoolExecutor-0_0, started daemon 15512)>
    │    │        │    └ (<weakref at 0x00000230B93E2958; to 'ThreadPoolExecutor' at 0x00000230B925B908>, <_queue.SimpleQueue object at 0x00000230B926...
    │    │        └ <Thread(ThreadPoolExecutor-0_0, started daemon 15512)>
    │    └ <function _worker at 0x00000230B927A3A8>
    └ <Thread(ThreadPoolExecutor-0_0, started daemon 15512)>

  File "C:\Users\admin\AppData\Local\Programs\Python\Python37\lib\concurrent\futures\thread.py", line 80, in _worker
    work_item.run()
    │         └ <function _WorkItem.run at 0x00000230B927A4C8>
    └ <concurrent.futures.thread._WorkItem object at 0x00000230B92BCC08>

  File "C:\Users\admin\AppData\Local\Programs\Python\Python37\lib\concurrent\futures\thread.py", line 57, in run
    result = self.fn(*self.args, **self.kwargs)
             │    │   │    │       │    └ {}
             │    │   │    │       └ <concurrent.futures.thread._WorkItem object at 0x00000230B92BCC08>
             │    │   │    └ [<grpc._cython.cygrpc.RequestCallEvent object at 0x00000230B93E26D8>, <grpc._server._RPCState object at 0x00000230B92CEEC8>, ...
             │    │   └ <concurrent.futures.thread._WorkItem object at 0x00000230B92BCC08>
             │    └ <function _unary_response_in_pool at 0x00000230B92ACC18>
             └ <concurrent.futures.thread._WorkItem object at 0x00000230B92BCC08>

  File "D:\virtual-environment\py3.7\lib\site-packages\grpc\_server.py", line 561, in _unary_response_in_pool
    argument, request_deserializer)
    │         └ <built-in method FromString of GeneratedProtocolMessageType object at 0x00000230B682B1F8>
    └ id: 11
      nick_name: "hugo"
      gender: "male"
      birthday: 1652976000

> File "D:\virtual-environment\py3.7\lib\site-packages\grpc\_server.py", line 443, in _call_behavior
    response_or_iterator = behavior(argument, context)
                           │        │         └ <grpc._server._Context object at 0x00000230B92DD788>
                           │        └ id: 11
                           │          nick_name: "hugo"
                           │          gender: "male"
                           │          birthday: 1652976000
                           │          
                           └ <bound method UserServicer.UpdateUser of <user_srv.handler.user.UserServicer object at 0x00000230B9275C08>>

  File "D:\PythonProjects\shop\user_srv\handler\user.py", line 106, in UpdateUser
    birthday = date.fromtimestamp(request.birthDay).strftime('%Y-%m-%d')
               │    │             └ id: 11
               │    │               nick_name: "hugo"
               │    │               gender: "male"
               │    │               birthday: 1652976000
               │    │               
               │    └ <method 'fromtimestamp' of 'datetime.date' objects>
               └ <class 'datetime.date'>

AttributeError: birthDay
2022-05-20 13:04:56.808 | INFO     | __main__:on_exit:41 - 注销4039beb8-d7fa-11ec-97fb-5800e3ca956e服务
2022-05-20 13:04:56.820 | INFO     | __main__:on_exit:43 - 服务注销成功
