2022-05-20 11:36:03.534 | INFO     | __main__:server:71 - 启动服务：192.168.23.1:63311
2022-05-20 11:36:03.738 | INFO     | __main__:server:73 - 服务注册开始
2022-05-20 11:36:03.818 | INFO     | __main__:server:79 - 服务注册成功
2022-05-20 11:41:25.032 | ERROR    | grpc._server:_call_behavior:443 - An error has been caught in function '_call_behavior', process 'MainProcess' (15212), thread 'ThreadPoolExecutor-0_4' (2144):
Traceback (most recent call last):

  File "C:\Users\admin\AppData\Local\Programs\Python\Python37\lib\threading.py", line 890, in _bootstrap
    self._bootstrap_inner()
    │    └ <function Thread._bootstrap_inner at 0x000002AF5340FAF8>
    └ <Thread(ThreadPoolExecutor-0_4, started daemon 2144)>

  File "C:\Users\admin\AppData\Local\Programs\Python\Python37\lib\threading.py", line 926, in _bootstrap_inner
    self.run()
    │    └ <function Thread.run at 0x000002AF5340F8B8>
    └ <Thread(ThreadPoolExecutor-0_4, started daemon 2144)>

  File "C:\Users\admin\AppData\Local\Programs\Python\Python37\lib\threading.py", line 870, in run
    self._target(*self._args, **self._kwargs)
    │    │        │    │        │    └ {}
    │    │        │    │        └ <Thread(ThreadPoolExecutor-0_4, started daemon 2144)>
    │    │        │    └ (<weakref at 0x000002AF55EDF4A8; to 'ThreadPoolExecutor' at 0x000002AF55D4AA48>, <_queue.SimpleQueue object at 0x000002AF55D5...
    │    │        └ <Thread(ThreadPoolExecutor-0_4, started daemon 2144)>
    │    └ <function _worker at 0x000002AF55D693A8>
    └ <Thread(ThreadPoolExecutor-0_4, started daemon 2144)>

  File "C:\Users\admin\AppData\Local\Programs\Python\Python37\lib\concurrent\futures\thread.py", line 80, in _worker
    work_item.run()
    │         └ <function _WorkItem.run at 0x000002AF55D694C8>
    └ <concurrent.futures.thread._WorkItem object at 0x000002AF55EF35C8>

  File "C:\Users\admin\AppData\Local\Programs\Python\Python37\lib\concurrent\futures\thread.py", line 57, in run
    result = self.fn(*self.args, **self.kwargs)
             │    │   │    │       │    └ {}
             │    │   │    │       └ <concurrent.futures.thread._WorkItem object at 0x000002AF55EF35C8>
             │    │   │    └ [<grpc._cython.cygrpc.RequestCallEvent object at 0x000002AF55EF25E8>, <grpc._server._RPCState object at 0x000002AF55EF3448>, ...
             │    │   └ <concurrent.futures.thread._WorkItem object at 0x000002AF55EF35C8>
             │    └ <function _unary_response_in_pool at 0x000002AF55D96A68>
             └ <concurrent.futures.thread._WorkItem object at 0x000002AF55EF35C8>

  File "D:\virtual-environment\py3.7\lib\site-packages\grpc\_server.py", line 561, in _unary_response_in_pool
    argument, request_deserializer)
    │         └ <built-in method FromString of GeneratedProtocolMessageType object at 0x000002AF532E99B8>
    └ id: 11
      nick_name: "hugo"
      gender: "male"
      birthday: 843667200

> File "D:\virtual-environment\py3.7\lib\site-packages\grpc\_server.py", line 443, in _call_behavior
    response_or_iterator = behavior(argument, context)
                           │        │         └ <grpc._server._Context object at 0x000002AF55EF3808>
                           │        └ id: 11
                           │          nick_name: "hugo"
                           │          gender: "male"
                           │          birthday: 843667200
                           │          
                           └ <bound method UserServicer.UpdateUser of <user_srv.handler.user.UserServicer object at 0x000002AF55D65E08>>

  File "D:\PythonProjects\shop\user_srv\handler\user.py", line 106, in UpdateUser
    formattime = date.fromtimestamp(request.birthDay)
                 │    │             └ id: 11
                 │    │               nick_name: "hugo"
                 │    │               gender: "male"
                 │    │               birthday: 843667200
                 │    │               
                 │    └ <method 'fromtimestamp' of 'datetime.date' objects>
                 └ <class 'datetime.date'>

AttributeError: birthDay
2022-05-20 11:43:32.616 | ERROR    | grpc._server:_call_behavior:443 - An error has been caught in function '_call_behavior', process 'MainProcess' (15212), thread 'ThreadPoolExecutor-0_2' (8568):
Traceback (most recent call last):

  File "C:\Users\admin\AppData\Local\Programs\Python\Python37\lib\threading.py", line 890, in _bootstrap
    self._bootstrap_inner()
    │    └ <function Thread._bootstrap_inner at 0x000002AF5340FAF8>
    └ <Thread(ThreadPoolExecutor-0_2, started daemon 8568)>

  File "C:\Users\admin\AppData\Local\Programs\Python\Python37\lib\threading.py", line 926, in _bootstrap_inner
    self.run()
    │    └ <function Thread.run at 0x000002AF5340F8B8>
    └ <Thread(ThreadPoolExecutor-0_2, started daemon 8568)>

  File "C:\Users\admin\AppData\Local\Programs\Python\Python37\lib\threading.py", line 870, in run
    self._target(*self._args, **self._kwargs)
    │    │        │    │        │    └ {}
    │    │        │    │        └ <Thread(ThreadPoolExecutor-0_2, started daemon 8568)>
    │    │        │    └ (<weakref at 0x000002AF55ED2EA8; to 'ThreadPoolExecutor' at 0x000002AF55D4AA48>, <_queue.SimpleQueue object at 0x000002AF55D5...
    │    │        └ <Thread(ThreadPoolExecutor-0_2, started daemon 8568)>
    │    └ <function _worker at 0x000002AF55D693A8>
    └ <Thread(ThreadPoolExecutor-0_2, started daemon 8568)>

  File "C:\Users\admin\AppData\Local\Programs\Python\Python37\lib\concurrent\futures\thread.py", line 80, in _worker
    work_item.run()
    │         └ <function _WorkItem.run at 0x000002AF55D694C8>
    └ <concurrent.futures.thread._WorkItem object at 0x000002AF561A2688>

  File "C:\Users\admin\AppData\Local\Programs\Python\Python37\lib\concurrent\futures\thread.py", line 57, in run
    result = self.fn(*self.args, **self.kwargs)
             │    │   │    │       │    └ {}
             │    │   │    │       └ <concurrent.futures.thread._WorkItem object at 0x000002AF561A2688>
             │    │   │    └ [<grpc._cython.cygrpc.RequestCallEvent object at 0x000002AF55EED778>, <grpc._server._RPCState object at 0x000002AF561A25C8>, ...
             │    │   └ <concurrent.futures.thread._WorkItem object at 0x000002AF561A2688>
             │    └ <function _unary_response_in_pool at 0x000002AF55D96A68>
             └ <concurrent.futures.thread._WorkItem object at 0x000002AF561A2688>

  File "D:\virtual-environment\py3.7\lib\site-packages\grpc\_server.py", line 561, in _unary_response_in_pool
    argument, request_deserializer)
    │         └ <built-in method FromString of GeneratedProtocolMessageType object at 0x000002AF532E99B8>
    └ id: 11
      nick_name: "hugo"
      gender: "male"
      birthday: 843667200

> File "D:\virtual-environment\py3.7\lib\site-packages\grpc\_server.py", line 443, in _call_behavior
    response_or_iterator = behavior(argument, context)
                           │        │         └ <grpc._server._Context object at 0x000002AF561A2848>
                           │        └ id: 11
                           │          nick_name: "hugo"
                           │          gender: "male"
                           │          birthday: 843667200
                           │          
                           └ <bound method UserServicer.UpdateUser of <user_srv.handler.user.UserServicer object at 0x000002AF55D65E08>>

  File "D:\PythonProjects\shop\user_srv\handler\user.py", line 106, in UpdateUser
    formattime = date.fromtimestamp(request.birthDay)
                 │    │             └ id: 11
                 │    │               nick_name: "hugo"
                 │    │               gender: "male"
                 │    │               birthday: 843667200
                 │    │               
                 │    └ <method 'fromtimestamp' of 'datetime.date' objects>
                 └ <class 'datetime.date'>

AttributeError: birthDay
2022-05-20 11:44:08.186 | ERROR    | grpc._server:_call_behavior:443 - An error has been caught in function '_call_behavior', process 'MainProcess' (15212), thread 'ThreadPoolExecutor-0_6' (14028):
Traceback (most recent call last):

  File "C:\Users\admin\AppData\Local\Programs\Python\Python37\lib\threading.py", line 890, in _bootstrap
    self._bootstrap_inner()
    │    └ <function Thread._bootstrap_inner at 0x000002AF5340FAF8>
    └ <Thread(ThreadPoolExecutor-0_6, started daemon 14028)>

  File "C:\Users\admin\AppData\Local\Programs\Python\Python37\lib\threading.py", line 926, in _bootstrap_inner
    self.run()
    │    └ <function Thread.run at 0x000002AF5340F8B8>
    └ <Thread(ThreadPoolExecutor-0_6, started daemon 14028)>

  File "C:\Users\admin\AppData\Local\Programs\Python\Python37\lib\threading.py", line 870, in run
    self._target(*self._args, **self._kwargs)
    │    │        │    │        │    └ {}
    │    │        │    │        └ <Thread(ThreadPoolExecutor-0_6, started daemon 14028)>
    │    │        │    └ (<weakref at 0x000002AF55EE34A8; to 'ThreadPoolExecutor' at 0x000002AF55D4AA48>, <_queue.SimpleQueue object at 0x000002AF55D5...
    │    │        └ <Thread(ThreadPoolExecutor-0_6, started daemon 14028)>
    │    └ <function _worker at 0x000002AF55D693A8>
    └ <Thread(ThreadPoolExecutor-0_6, started daemon 14028)>

  File "C:\Users\admin\AppData\Local\Programs\Python\Python37\lib\concurrent\futures\thread.py", line 80, in _worker
    work_item.run()
    │         └ <function _WorkItem.run at 0x000002AF55D694C8>
    └ <concurrent.futures.thread._WorkItem object at 0x000002AF561AA608>

  File "C:\Users\admin\AppData\Local\Programs\Python\Python37\lib\concurrent\futures\thread.py", line 57, in run
    result = self.fn(*self.args, **self.kwargs)
             │    │   │    │       │    └ {}
             │    │   │    │       └ <concurrent.futures.thread._WorkItem object at 0x000002AF561AA608>
             │    │   │    └ [<grpc._cython.cygrpc.RequestCallEvent object at 0x000002AF55EED818>, <grpc._server._RPCState object at 0x000002AF561AA408>, ...
             │    │   └ <concurrent.futures.thread._WorkItem object at 0x000002AF561AA608>
             │    └ <function _unary_response_in_pool at 0x000002AF55D96A68>
             └ <concurrent.futures.thread._WorkItem object at 0x000002AF561AA608>

  File "D:\virtual-environment\py3.7\lib\site-packages\grpc\_server.py", line 561, in _unary_response_in_pool
    argument, request_deserializer)
    │         └ <built-in method FromString of GeneratedProtocolMessageType object at 0x000002AF532E99B8>
    └ id: 11
      nick_name: "hugo"
      gender: "male"
      birthday: 843667200

> File "D:\virtual-environment\py3.7\lib\site-packages\grpc\_server.py", line 443, in _call_behavior
    response_or_iterator = behavior(argument, context)
                           │        │         └ <grpc._server._Context object at 0x000002AF561AA788>
                           │        └ id: 11
                           │          nick_name: "hugo"
                           │          gender: "male"
                           │          birthday: 843667200
                           │          
                           └ <bound method UserServicer.UpdateUser of <user_srv.handler.user.UserServicer object at 0x000002AF55D65E08>>

  File "D:\PythonProjects\shop\user_srv\handler\user.py", line 106, in UpdateUser
    formattime = date.fromtimestamp(request.birthDay)
                 │    │             └ id: 11
                 │    │               nick_name: "hugo"
                 │    │               gender: "male"
                 │    │               birthday: 843667200
                 │    │               
                 │    └ <method 'fromtimestamp' of 'datetime.date' objects>
                 └ <class 'datetime.date'>

AttributeError: birthDay
2022-05-20 11:44:48.295 | ERROR    | grpc._server:_call_behavior:443 - An error has been caught in function '_call_behavior', process 'MainProcess' (15212), thread 'ThreadPoolExecutor-0_8' (3916):
Traceback (most recent call last):

  File "C:\Users\admin\AppData\Local\Programs\Python\Python37\lib\threading.py", line 890, in _bootstrap
    self._bootstrap_inner()
    │    └ <function Thread._bootstrap_inner at 0x000002AF5340FAF8>
    └ <Thread(ThreadPoolExecutor-0_8, started daemon 3916)>

  File "C:\Users\admin\AppData\Local\Programs\Python\Python37\lib\threading.py", line 926, in _bootstrap_inner
    self.run()
    │    └ <function Thread.run at 0x000002AF5340F8B8>
    └ <Thread(ThreadPoolExecutor-0_8, started daemon 3916)>

  File "C:\Users\admin\AppData\Local\Programs\Python\Python37\lib\threading.py", line 870, in run
    self._target(*self._args, **self._kwargs)
    │    │        │    │        │    └ {}
    │    │        │    │        └ <Thread(ThreadPoolExecutor-0_8, started daemon 3916)>
    │    │        │    └ (<weakref at 0x000002AF55EE3CC8; to 'ThreadPoolExecutor' at 0x000002AF55D4AA48>, <_queue.SimpleQueue object at 0x000002AF55D5...
    │    │        └ <Thread(ThreadPoolExecutor-0_8, started daemon 3916)>
    │    └ <function _worker at 0x000002AF55D693A8>
    └ <Thread(ThreadPoolExecutor-0_8, started daemon 3916)>

  File "C:\Users\admin\AppData\Local\Programs\Python\Python37\lib\concurrent\futures\thread.py", line 80, in _worker
    work_item.run()
    │         └ <function _WorkItem.run at 0x000002AF55D694C8>
    └ <concurrent.futures.thread._WorkItem object at 0x000002AF561B2648>

  File "C:\Users\admin\AppData\Local\Programs\Python\Python37\lib\concurrent\futures\thread.py", line 57, in run
    result = self.fn(*self.args, **self.kwargs)
             │    │   │    │       │    └ {}
             │    │   │    │       └ <concurrent.futures.thread._WorkItem object at 0x000002AF561B2648>
             │    │   │    └ [<grpc._cython.cygrpc.RequestCallEvent object at 0x000002AF55EF2098>, <grpc._server._RPCState object at 0x000002AF561B2808>, ...
             │    │   └ <concurrent.futures.thread._WorkItem object at 0x000002AF561B2648>
             │    └ <function _unary_response_in_pool at 0x000002AF55D96A68>
             └ <concurrent.futures.thread._WorkItem object at 0x000002AF561B2648>

  File "D:\virtual-environment\py3.7\lib\site-packages\grpc\_server.py", line 561, in _unary_response_in_pool
    argument, request_deserializer)
    │         └ <built-in method FromString of GeneratedProtocolMessageType object at 0x000002AF532E99B8>
    └ id: 11
      nick_name: "hugo"
      gender: "male"
      birthday: 843667200

> File "D:\virtual-environment\py3.7\lib\site-packages\grpc\_server.py", line 443, in _call_behavior
    response_or_iterator = behavior(argument, context)
                           │        │         └ <grpc._server._Context object at 0x000002AF561B2848>
                           │        └ id: 11
                           │          nick_name: "hugo"
                           │          gender: "male"
                           │          birthday: 843667200
                           │          
                           └ <bound method UserServicer.UpdateUser of <user_srv.handler.user.UserServicer object at 0x000002AF55D65E08>>

  File "D:\PythonProjects\shop\user_srv\handler\user.py", line 106, in UpdateUser
    formattime = date.fromtimestamp(request.birthDay)
                 │    │             └ id: 11
                 │    │               nick_name: "hugo"
                 │    │               gender: "male"
                 │    │               birthday: 843667200
                 │    │               
                 │    └ <method 'fromtimestamp' of 'datetime.date' objects>
                 └ <class 'datetime.date'>

AttributeError: birthDay
2022-05-20 11:49:24.626 | ERROR    | grpc._server:_call_behavior:443 - An error has been caught in function '_call_behavior', process 'MainProcess' (15212), thread 'ThreadPoolExecutor-0_4' (2144):
Traceback (most recent call last):

  File "C:\Users\admin\AppData\Local\Programs\Python\Python37\lib\threading.py", line 890, in _bootstrap
    self._bootstrap_inner()
    │    └ <function Thread._bootstrap_inner at 0x000002AF5340FAF8>
    └ <Thread(ThreadPoolExecutor-0_4, started daemon 2144)>

  File "C:\Users\admin\AppData\Local\Programs\Python\Python37\lib\threading.py", line 926, in _bootstrap_inner
    self.run()
    │    └ <function Thread.run at 0x000002AF5340F8B8>
    └ <Thread(ThreadPoolExecutor-0_4, started daemon 2144)>

  File "C:\Users\admin\AppData\Local\Programs\Python\Python37\lib\threading.py", line 870, in run
    self._target(*self._args, **self._kwargs)
    │    │        │    │        │    └ {}
    │    │        │    │        └ <Thread(ThreadPoolExecutor-0_4, started daemon 2144)>
    │    │        │    └ (<weakref at 0x000002AF55EDF4A8; to 'ThreadPoolExecutor' at 0x000002AF55D4AA48>, <_queue.SimpleQueue object at 0x000002AF55D5...
    │    │        └ <Thread(ThreadPoolExecutor-0_4, started daemon 2144)>
    │    └ <function _worker at 0x000002AF55D693A8>
    └ <Thread(ThreadPoolExecutor-0_4, started daemon 2144)>

  File "C:\Users\admin\AppData\Local\Programs\Python\Python37\lib\concurrent\futures\thread.py", line 80, in _worker
    work_item.run()
    │         └ <function _WorkItem.run at 0x000002AF55D694C8>
    └ <concurrent.futures.thread._WorkItem object at 0x000002AF561C4FC8>

  File "C:\Users\admin\AppData\Local\Programs\Python\Python37\lib\concurrent\futures\thread.py", line 57, in run
    result = self.fn(*self.args, **self.kwargs)
             │    │   │    │       │    └ {}
             │    │   │    │       └ <concurrent.futures.thread._WorkItem object at 0x000002AF561C4FC8>
             │    │   │    └ [<grpc._cython.cygrpc.RequestCallEvent object at 0x000002AF561C64F8>, <grpc._server._RPCState object at 0x000002AF561C4788>, ...
             │    │   └ <concurrent.futures.thread._WorkItem object at 0x000002AF561C4FC8>
             │    └ <function _unary_response_in_pool at 0x000002AF55D96A68>
             └ <concurrent.futures.thread._WorkItem object at 0x000002AF561C4FC8>

  File "D:\virtual-environment\py3.7\lib\site-packages\grpc\_server.py", line 561, in _unary_response_in_pool
    argument, request_deserializer)
    │         └ <built-in method FromString of GeneratedProtocolMessageType object at 0x000002AF532E99B8>
    └ id: 11
      nick_name: "hugo"
      gender: "male"
      birthday: 843667200

> File "D:\virtual-environment\py3.7\lib\site-packages\grpc\_server.py", line 443, in _call_behavior
    response_or_iterator = behavior(argument, context)
                           │        │         └ <grpc._server._Context object at 0x000002AF561C70C8>
                           │        └ id: 11
                           │          nick_name: "hugo"
                           │          gender: "male"
                           │          birthday: 843667200
                           │          
                           └ <bound method UserServicer.UpdateUser of <user_srv.handler.user.UserServicer object at 0x000002AF55D65E08>>

  File "D:\PythonProjects\shop\user_srv\handler\user.py", line 106, in UpdateUser
    formattime = date.fromtimestamp(request.birthDay)
                 │    │             └ id: 11
                 │    │               nick_name: "hugo"
                 │    │               gender: "male"
                 │    │               birthday: 843667200
                 │    │               
                 │    └ <method 'fromtimestamp' of 'datetime.date' objects>
                 └ <class 'datetime.date'>

AttributeError: birthDay
2022-05-20 11:49:52.168 | ERROR    | grpc._server:_call_behavior:443 - An error has been caught in function '_call_behavior', process 'MainProcess' (15212), thread 'ThreadPoolExecutor-0_2' (8568):
Traceback (most recent call last):

  File "C:\Users\admin\AppData\Local\Programs\Python\Python37\lib\threading.py", line 890, in _bootstrap
    self._bootstrap_inner()
    │    └ <function Thread._bootstrap_inner at 0x000002AF5340FAF8>
    └ <Thread(ThreadPoolExecutor-0_2, started daemon 8568)>

  File "C:\Users\admin\AppData\Local\Programs\Python\Python37\lib\threading.py", line 926, in _bootstrap_inner
    self.run()
    │    └ <function Thread.run at 0x000002AF5340F8B8>
    └ <Thread(ThreadPoolExecutor-0_2, started daemon 8568)>

  File "C:\Users\admin\AppData\Local\Programs\Python\Python37\lib\threading.py", line 870, in run
    self._target(*self._args, **self._kwargs)
    │    │        │    │        │    └ {}
    │    │        │    │        └ <Thread(ThreadPoolExecutor-0_2, started daemon 8568)>
    │    │        │    └ (<weakref at 0x000002AF55ED2EA8; to 'ThreadPoolExecutor' at 0x000002AF55D4AA48>, <_queue.SimpleQueue object at 0x000002AF55D5...
    │    │        └ <Thread(ThreadPoolExecutor-0_2, started daemon 8568)>
    │    └ <function _worker at 0x000002AF55D693A8>
    └ <Thread(ThreadPoolExecutor-0_2, started daemon 8568)>

  File "C:\Users\admin\AppData\Local\Programs\Python\Python37\lib\concurrent\futures\thread.py", line 80, in _worker
    work_item.run()
    │         └ <function _WorkItem.run at 0x000002AF55D694C8>
    └ <concurrent.futures.thread._WorkItem object at 0x000002AF561C3308>

  File "C:\Users\admin\AppData\Local\Programs\Python\Python37\lib\concurrent\futures\thread.py", line 57, in run
    result = self.fn(*self.args, **self.kwargs)
             │    │   │    │       │    └ {}
             │    │   │    │       └ <concurrent.futures.thread._WorkItem object at 0x000002AF561C3308>
             │    │   │    └ [<grpc._cython.cygrpc.RequestCallEvent object at 0x000002AF561C62C8>, <grpc._server._RPCState object at 0x000002AF561C3648>, ...
             │    │   └ <concurrent.futures.thread._WorkItem object at 0x000002AF561C3308>
             │    └ <function _unary_response_in_pool at 0x000002AF55D96A68>
             └ <concurrent.futures.thread._WorkItem object at 0x000002AF561C3308>

  File "D:\virtual-environment\py3.7\lib\site-packages\grpc\_server.py", line 561, in _unary_response_in_pool
    argument, request_deserializer)
    │         └ <built-in method FromString of GeneratedProtocolMessageType object at 0x000002AF532E99B8>
    └ id: 11
      nick_name: "hugo"
      gender: "male"
      birthday: 18446744073709522816

> File "D:\virtual-environment\py3.7\lib\site-packages\grpc\_server.py", line 443, in _call_behavior
    response_or_iterator = behavior(argument, context)
                           │        │         └ <grpc._server._Context object at 0x000002AF561C3D88>
                           │        └ id: 11
                           │          nick_name: "hugo"
                           │          gender: "male"
                           │          birthday: 18446744073709522816
                           │          
                           └ <bound method UserServicer.UpdateUser of <user_srv.handler.user.UserServicer object at 0x000002AF55D65E08>>

  File "D:\PythonProjects\shop\user_srv\handler\user.py", line 106, in UpdateUser
    formattime = date.fromtimestamp(request.birthDay)
                 │    │             └ id: 11
                 │    │               nick_name: "hugo"
                 │    │               gender: "male"
                 │    │               birthday: 18446744073709522816
                 │    │               
                 │    └ <method 'fromtimestamp' of 'datetime.date' objects>
                 └ <class 'datetime.date'>

AttributeError: birthDay
2022-05-20 11:51:37.985 | ERROR    | grpc._server:_call_behavior:443 - An error has been caught in function '_call_behavior', process 'MainProcess' (15212), thread 'ThreadPoolExecutor-0_3' (9512):
Traceback (most recent call last):

  File "C:\Users\admin\AppData\Local\Programs\Python\Python37\lib\threading.py", line 890, in _bootstrap
    self._bootstrap_inner()
    │    └ <function Thread._bootstrap_inner at 0x000002AF5340FAF8>
    └ <Thread(ThreadPoolExecutor-0_3, started daemon 9512)>

  File "C:\Users\admin\AppData\Local\Programs\Python\Python37\lib\threading.py", line 926, in _bootstrap_inner
    self.run()
    │    └ <function Thread.run at 0x000002AF5340F8B8>
    └ <Thread(ThreadPoolExecutor-0_3, started daemon 9512)>

  File "C:\Users\admin\AppData\Local\Programs\Python\Python37\lib\threading.py", line 870, in run
    self._target(*self._args, **self._kwargs)
    │    │        │    │        │    └ {}
    │    │        │    │        └ <Thread(ThreadPoolExecutor-0_3, started daemon 9512)>
    │    │        │    └ (<weakref at 0x000002AF55EDF1D8; to 'ThreadPoolExecutor' at 0x000002AF55D4AA48>, <_queue.SimpleQueue object at 0x000002AF55D5...
    │    │        └ <Thread(ThreadPoolExecutor-0_3, started daemon 9512)>
    │    └ <function _worker at 0x000002AF55D693A8>
    └ <Thread(ThreadPoolExecutor-0_3, started daemon 9512)>

  File "C:\Users\admin\AppData\Local\Programs\Python\Python37\lib\concurrent\futures\thread.py", line 80, in _worker
    work_item.run()
    │         └ <function _WorkItem.run at 0x000002AF55D694C8>
    └ <concurrent.futures.thread._WorkItem object at 0x000002AF561BC388>

  File "C:\Users\admin\AppData\Local\Programs\Python\Python37\lib\concurrent\futures\thread.py", line 57, in run
    result = self.fn(*self.args, **self.kwargs)
             │    │   │    │       │    └ {}
             │    │   │    │       └ <concurrent.futures.thread._WorkItem object at 0x000002AF561BC388>
             │    │   │    └ [<grpc._cython.cygrpc.RequestCallEvent object at 0x000002AF561C83B8>, <grpc._server._RPCState object at 0x000002AF561BC948>, ...
             │    │   └ <concurrent.futures.thread._WorkItem object at 0x000002AF561BC388>
             │    └ <function _unary_response_in_pool at 0x000002AF55D96A68>
             └ <concurrent.futures.thread._WorkItem object at 0x000002AF561BC388>

  File "D:\virtual-environment\py3.7\lib\site-packages\grpc\_server.py", line 561, in _unary_response_in_pool
    argument, request_deserializer)
    │         └ <built-in method FromString of GeneratedProtocolMessageType object at 0x000002AF532E99B8>
    └ id: 11
      nick_name: "hugo"
      gender: "male"
      birthday: 18446744073709522816

> File "D:\virtual-environment\py3.7\lib\site-packages\grpc\_server.py", line 443, in _call_behavior
    response_or_iterator = behavior(argument, context)
                           │        │         └ <grpc._server._Context object at 0x000002AF561BC848>
                           │        └ id: 11
                           │          nick_name: "hugo"
                           │          gender: "male"
                           │          birthday: 18446744073709522816
                           │          
                           └ <bound method UserServicer.UpdateUser of <user_srv.handler.user.UserServicer object at 0x000002AF55D65E08>>

  File "D:\PythonProjects\shop\user_srv\handler\user.py", line 106, in UpdateUser
    formattime = date.fromtimestamp(request.birthDay)
                 │    │             └ id: 11
                 │    │               nick_name: "hugo"
                 │    │               gender: "male"
                 │    │               birthday: 18446744073709522816
                 │    │               
                 │    └ <method 'fromtimestamp' of 'datetime.date' objects>
                 └ <class 'datetime.date'>

AttributeError: birthDay
2022-05-20 12:09:51.824 | INFO     | __main__:on_exit:41 - 注销f988926c-d7ed-11ec-a461-5800e3ca956e服务
2022-05-20 12:09:51.833 | INFO     | __main__:on_exit:43 - 服务注销成功
