2022-05-20 10:55:58.751 | INFO     | __main__:server:71 - 启动服务：192.168.23.1:55476
2022-05-20 10:55:58.754 | INFO     | __main__:server:73 - 服务注册开始
2022-05-20 10:55:58.788 | INFO     | __main__:server:79 - 服务注册成功
2022-05-20 10:56:11.172 | ERROR    | grpc._server:_call_behavior:443 - An error has been caught in function '_call_behavior', process 'MainProcess' (5668), thread 'ThreadPoolExecutor-0_0' (14704):
Traceback (most recent call last):

  File "D:\pycharm\PyCharm 2021.1.3\plugins\python\helpers\pydev\_pydev_bundle\pydev_monkey.py", line 795, in __call__
    ret = self.original_func(*self.args, **self.kwargs)
          │    │              │    │       │    └ {}
          │    │              │    │       └ <_pydev_bundle.pydev_monkey._NewThreadStartupWithTrace object at 0x000001F927135548>
          │    │              │    └ ()
          │    │              └ <_pydev_bundle.pydev_monkey._NewThreadStartupWithTrace object at 0x000001F927135548>
          │    └ <bound method Thread._bootstrap of <Thread(ThreadPoolExecutor-0_0, started daemon 14704)>>
          └ <_pydev_bundle.pydev_monkey._NewThreadStartupWithTrace object at 0x000001F927135548>

  File "C:\Users\admin\AppData\Local\Programs\Python\Python37\lib\threading.py", line 890, in _bootstrap
    self._bootstrap_inner()
    │    └ <function Thread._bootstrap_inner at 0x000001F908F1DD38>
    └ <Thread(ThreadPoolExecutor-0_0, started daemon 14704)>

  File "C:\Users\admin\AppData\Local\Programs\Python\Python37\lib\threading.py", line 926, in _bootstrap_inner
    self.run()
    │    └ <function Thread.run at 0x000001F908F1DAF8>
    └ <Thread(ThreadPoolExecutor-0_0, started daemon 14704)>

  File "C:\Users\admin\AppData\Local\Programs\Python\Python37\lib\threading.py", line 870, in run
    self._target(*self._args, **self._kwargs)
    │    │        │    │        │    └ {}
    │    │        │    │        └ <Thread(ThreadPoolExecutor-0_0, started daemon 14704)>
    │    │        │    └ (<weakref at 0x000001F927242BD8; to 'ThreadPoolExecutor' at 0x000001F9270A7A48>, <_queue.SimpleQueue object at 0x000001F9270C...
    │    │        └ <Thread(ThreadPoolExecutor-0_0, started daemon 14704)>
    │    └ <function _worker at 0x000001F9270CF168>
    └ <Thread(ThreadPoolExecutor-0_0, started daemon 14704)>

  File "C:\Users\admin\AppData\Local\Programs\Python\Python37\lib\concurrent\futures\thread.py", line 80, in _worker
    work_item.run()
    │         └ <function _WorkItem.run at 0x000001F9270CF318>
    └ <concurrent.futures.thread._WorkItem object at 0x000001F927135888>

  File "C:\Users\admin\AppData\Local\Programs\Python\Python37\lib\concurrent\futures\thread.py", line 57, in run
    result = self.fn(*self.args, **self.kwargs)
             │    │   │    │       │    └ {}
             │    │   │    │       └ <concurrent.futures.thread._WorkItem object at 0x000001F927135888>
             │    │   │    └ [<grpc._cython.cygrpc.RequestCallEvent object at 0x000001F9271219F8>, <grpc._server._RPCState object at 0x000001F9271358C8>, ...
             │    │   └ <concurrent.futures.thread._WorkItem object at 0x000001F927135888>
             │    └ <function _unary_response_in_pool at 0x000001F9271009D8>
             └ <concurrent.futures.thread._WorkItem object at 0x000001F927135888>

  File "D:\virtual-environment\py3.7\lib\site-packages\grpc\_server.py", line 561, in _unary_response_in_pool
    argument, request_deserializer)
    │         └ <built-in method FromString of GeneratedProtocolMessageType object at 0x000001F92425EA68>
    └ id: 11
      nick_name: "hugo"
      gender: "male"
      birthday: 18446744011573954816

> File "D:\virtual-environment\py3.7\lib\site-packages\grpc\_server.py", line 443, in _call_behavior
    response_or_iterator = behavior(argument, context)
                           │        │         └ <grpc._server._Context object at 0x000001F927135088>
                           │        └ id: 11
                           │          nick_name: "hugo"
                           │          gender: "male"
                           │          birthday: 18446744011573954816
                           │          
                           └ <bound method UserServicer.UpdateUser of <user_srv.handler.user.UserServicer object at 0x000001F9270CE3C8>>

  File "D:\PythonProjects\shop\user_srv\handler\user.py", line 106, in UpdateUser
    user.birthday = time.strftime("%Y-%m-%d %H:%M:%S", time.localtime(request.birthday))
    │    │          │    │                             │    │         │       └ <field property 'UpdateUserInfo.birthday'>
    │    │          │    │                             │    │         └ id: 11
    │    │          │    │                             │    │           nick_name: "hugo"
    │    │          │    │                             │    │           gender: "male"
    │    │          │    │                             │    │           birthday: 18446744011573954816
    │    │          │    │                             │    │           
    │    │          │    │                             │    └ <built-in function localtime>
    │    │          │    │                             └ <module 'time' (built-in)>
    │    │          │    └ <built-in function strftime>
    │    │          └ <module 'time' (built-in)>
    │    └ <peewee.FieldAccessor object at 0x000001F92450B808>
    └ <User: 11>

OverflowError: timestamp out of range for platform time_t
