2022-05-20 11:44:06.419 | INFO     | __main__:server:71 - 启动服务：192.168.23.1:64926
2022-05-20 11:44:06.422 | INFO     | __main__:server:73 - 服务注册开始
2022-05-20 11:44:06.441 | INFO     | __main__:server:79 - 服务注册成功
2022-05-20 11:44:17.717 | ERROR    | grpc._server:_call_behavior:443 - An error has been caught in function '_call_behavior', process 'MainProcess' (10360), thread 'ThreadPoolExecutor-0_1' (11524):
Traceback (most recent call last):

  File "D:\pycharm\PyCharm 2021.1.3\plugins\python\helpers\pydev\_pydev_bundle\pydev_monkey.py", line 795, in __call__
    ret = self.original_func(*self.args, **self.kwargs)
          │    │              │    │       │    └ {}
          │    │              │    │       └ <_pydev_bundle.pydev_monkey._NewThreadStartupWithTrace object at 0x000002BA31175188>
          │    │              │    └ ()
          │    │              └ <_pydev_bundle.pydev_monkey._NewThreadStartupWithTrace object at 0x000002BA31175188>
          │    └ <bound method Thread._bootstrap of <Thread(ThreadPoolExecutor-0_1, started daemon 11524)>>
          └ <_pydev_bundle.pydev_monkey._NewThreadStartupWithTrace object at 0x000002BA31175188>

  File "C:\Users\admin\AppData\Local\Programs\Python\Python37\lib\threading.py", line 890, in _bootstrap
    self._bootstrap_inner()
    │    └ <function Thread._bootstrap_inner at 0x000002BA1304DD38>
    └ <Thread(ThreadPoolExecutor-0_1, started daemon 11524)>

  File "C:\Users\admin\AppData\Local\Programs\Python\Python37\lib\threading.py", line 926, in _bootstrap_inner
    self.run()
    │    └ <function Thread.run at 0x000002BA1304DAF8>
    └ <Thread(ThreadPoolExecutor-0_1, started daemon 11524)>

  File "C:\Users\admin\AppData\Local\Programs\Python\Python37\lib\threading.py", line 870, in run
    self._target(*self._args, **self._kwargs)
    │    │        │    │        │    └ {}
    │    │        │    │        └ <Thread(ThreadPoolExecutor-0_1, started daemon 11524)>
    │    │        │    └ (<weakref at 0x000002BA3118A098; to 'ThreadPoolExecutor' at 0x000002BA30FE00C8>, <_queue.SimpleQueue object at 0x000002BA30FF...
    │    │        └ <Thread(ThreadPoolExecutor-0_1, started daemon 11524)>
    │    └ <function _worker at 0x000002BA30FFF168>
    └ <Thread(ThreadPoolExecutor-0_1, started daemon 11524)>

  File "C:\Users\admin\AppData\Local\Programs\Python\Python37\lib\concurrent\futures\thread.py", line 80, in _worker
    work_item.run()
    │         └ <function _WorkItem.run at 0x000002BA30FFF318>
    └ <concurrent.futures.thread._WorkItem object at 0x000002BA31060B48>

  File "C:\Users\admin\AppData\Local\Programs\Python\Python37\lib\concurrent\futures\thread.py", line 57, in run
    result = self.fn(*self.args, **self.kwargs)
             │    │   │    │       │    └ {}
             │    │   │    │       └ <concurrent.futures.thread._WorkItem object at 0x000002BA31060B48>
             │    │   │    └ [<grpc._cython.cygrpc.RequestCallEvent object at 0x000002BA31051908>, <grpc._server._RPCState object at 0x000002BA31060108>, ...
             │    │   └ <concurrent.futures.thread._WorkItem object at 0x000002BA31060B48>
             │    └ <function _unary_response_in_pool at 0x000002BA31030A68>
             └ <concurrent.futures.thread._WorkItem object at 0x000002BA31060B48>

  File "D:\virtual-environment\py3.7\lib\site-packages\grpc\_server.py", line 561, in _unary_response_in_pool
    argument, request_deserializer)
    │         └ <built-in method FromString of GeneratedProtocolMessageType object at 0x000002BA2DBC5B68>
    └ id: 11
      nick_name: "hugo"
      gender: "male"
      birthday: 843667200

> File "D:\virtual-environment\py3.7\lib\site-packages\grpc\_server.py", line 443, in _call_behavior
    response_or_iterator = behavior(argument, context)
                           │        │         └ <grpc._server._Context object at 0x000002BA311755C8>
                           │        └ id: 11
                           │          nick_name: "hugo"
                           │          gender: "male"
                           │          birthday: 843667200
                           │          
                           └ <bound method UserServicer.UpdateUser of <user_srv.handler.user.UserServicer object at 0x000002BA30FFE448>>

  File "D:\PythonProjects\shop\user_srv\handler\user.py", line 106, in UpdateUser
    formattime = date.fromtimestamp(request.birthDay)
                 │    │             └ id: 11
                 │    │               nick_name: "hugo"
                 │    │               gender: "male"
                 │    │               birthday: 843667200
                 │    │               
                 │    └ <method 'fromtimestamp' of 'datetime.date' objects>
                 └ <class 'datetime.date'>

AttributeError: birthDay
