2022-05-20 12:43:24.826 | INFO     | __main__:server:71 - 启动服务：192.168.23.1:54821
2022-05-20 12:43:24.828 | INFO     | __main__:server:73 - 服务注册开始
2022-05-20 12:43:25.069 | INFO     | __main__:server:79 - 服务注册成功
2022-05-20 12:44:59.836 | ERROR    | grpc._server:_call_behavior:443 - An error has been caught in function '_call_behavior', process 'MainProcess' (16924), thread 'ThreadPoolExecutor-0_3' (13660):
Traceback (most recent call last):

  File "D:\pycharm\PyCharm 2021.1.3\plugins\python\helpers\pydev\_pydev_bundle\pydev_monkey.py", line 795, in __call__
    ret = self.original_func(*self.args, **self.kwargs)
          │    │              │    │       │    └ {}
          │    │              │    │       └ <_pydev_bundle.pydev_monkey._NewThreadStartupWithTrace object at 0x000001379C4F4708>
          │    │              │    └ ()
          │    │              └ <_pydev_bundle.pydev_monkey._NewThreadStartupWithTrace object at 0x000001379C4F4708>
          │    └ <bound method Thread._bootstrap of <Thread(ThreadPoolExecutor-0_3, started daemon 13660)>>
          └ <_pydev_bundle.pydev_monkey._NewThreadStartupWithTrace object at 0x000001379C4F4708>

  File "C:\Users\admin\AppData\Local\Programs\Python\Python37\lib\threading.py", line 890, in _bootstrap
    self._bootstrap_inner()
    │    └ <function Thread._bootstrap_inner at 0x00000137FE3BDD38>
    └ <Thread(ThreadPoolExecutor-0_3, started daemon 13660)>

  File "C:\Users\admin\AppData\Local\Programs\Python\Python37\lib\threading.py", line 926, in _bootstrap_inner
    self.run()
    │    └ <function Thread.run at 0x00000137FE3BDAF8>
    └ <Thread(ThreadPoolExecutor-0_3, started daemon 13660)>

  File "C:\Users\admin\AppData\Local\Programs\Python\Python37\lib\threading.py", line 870, in run
    self._target(*self._args, **self._kwargs)
    │    │        │    │        │    └ {}
    │    │        │    │        └ <Thread(ThreadPoolExecutor-0_3, started daemon 13660)>
    │    │        │    └ (<weakref at 0x000001379C508EF8; to 'ThreadPoolExecutor' at 0x000001379C356B88>, <_queue.SimpleQueue object at 0x000001379C37...
    │    │        └ <Thread(ThreadPoolExecutor-0_3, started daemon 13660)>
    │    └ <function _worker at 0x000001379C37F168>
    └ <Thread(ThreadPoolExecutor-0_3, started daemon 13660)>

  File "C:\Users\admin\AppData\Local\Programs\Python\Python37\lib\concurrent\futures\thread.py", line 80, in _worker
    work_item.run()
    │         └ <function _WorkItem.run at 0x000001379C37F318>
    └ <concurrent.futures.thread._WorkItem object at 0x000001379C527788>

  File "C:\Users\admin\AppData\Local\Programs\Python\Python37\lib\concurrent\futures\thread.py", line 57, in run
    result = self.fn(*self.args, **self.kwargs)
             │    │   │    │       │    └ {}
             │    │   │    │       └ <concurrent.futures.thread._WorkItem object at 0x000001379C527788>
             │    │   │    └ [<grpc._cython.cygrpc.RequestCallEvent object at 0x000001379C524B38>, <grpc._server._RPCState object at 0x000001379C5275C8>, ...
             │    │   └ <concurrent.futures.thread._WorkItem object at 0x000001379C527788>
             │    └ <function _unary_response_in_pool at 0x000001379C3B1A68>
             └ <concurrent.futures.thread._WorkItem object at 0x000001379C527788>

  File "D:\virtual-environment\py3.7\lib\site-packages\grpc\_server.py", line 561, in _unary_response_in_pool
    argument, request_deserializer)
    │         └ <built-in method FromString of GeneratedProtocolMessageType object at 0x00000137994722F8>
    └ id: 11
      nick_name: "hugo"
      gender: "male"
      birthday: 1652976000

> File "D:\virtual-environment\py3.7\lib\site-packages\grpc\_server.py", line 443, in _call_behavior
    response_or_iterator = behavior(argument, context)
                           │        │         └ <grpc._server._Context object at 0x000001379C527848>
                           │        └ id: 11
                           │          nick_name: "hugo"
                           │          gender: "male"
                           │          birthday: 1652976000
                           │          
                           └ <bound method UserServicer.UpdateUser of <user_srv.handler.user.UserServicer object at 0x000001379C37DA48>>

  File "D:\PythonProjects\shop\user_srv\handler\user.py", line 106, in UpdateUser
    user.birthday = date.fromtimestamp(request.birthDay)
    │    │          │    │             └ id: 11
    │    │          │    │               nick_name: "hugo"
    │    │          │    │               gender: "male"
    │    │          │    │               birthday: 1652976000
    │    │          │    │               
    │    │          │    └ <method 'fromtimestamp' of 'datetime.date' objects>
    │    │          └ <class 'datetime.date'>
    │    └ <peewee.FieldAccessor object at 0x00000137997AAB88>
    └ <User: 11>

AttributeError: birthDay
