2022-05-18 17:12:40.658 | INFO     | __main__:server:76 - 启动服务：192.168.23.1:56398
2022-05-18 17:12:40.666 | INFO     | __main__:server:79 - 服务注册开始
2022-05-18 17:12:40.684 | INFO     | __main__:server:86 - 服务注册成功
2022-05-18 17:14:03.392 | ERROR    | grpc._server:_call_behavior:443 - An error has been caught in function '_call_behavior', process 'MainProcess' (6420), thread 'ThreadPoolExecutor-0_1' (3172):
Traceback (most recent call last):

  File "D:\PythonProjects\shop\user_operation_srv\handler\message.py", line 57, in DeleteMessage
    return empty_pb2.Empty()

NameError: name 'empty_pb2' is not defined


During handling of the above exception, another exception occurred:


Traceback (most recent call last):

  File "C:\Users\admin\AppData\Local\Programs\Python\Python37\lib\threading.py", line 890, in _bootstrap
    self._bootstrap_inner()
    │    └ <function Thread._bootstrap_inner at 0x000002520B8CFAF8>
    └ <Thread(ThreadPoolExecutor-0_1, started daemon 3172)>

  File "C:\Users\admin\AppData\Local\Programs\Python\Python37\lib\threading.py", line 926, in _bootstrap_inner
    self.run()
    │    └ <function Thread.run at 0x000002520B8CF8B8>
    └ <Thread(ThreadPoolExecutor-0_1, started daemon 3172)>

  File "C:\Users\admin\AppData\Local\Programs\Python\Python37\lib\threading.py", line 870, in run
    self._target(*self._args, **self._kwargs)
    │    │        │    │        │    └ {}
    │    │        │    │        └ <Thread(ThreadPoolExecutor-0_1, started daemon 3172)>
    │    │        │    └ (<weakref at 0x000002520E556B38; to 'ThreadPoolExecutor' at 0x000002520E4E4FC8>, <_queue.SimpleQueue object at 0x000002520E4E...
    │    │        └ <Thread(ThreadPoolExecutor-0_1, started daemon 3172)>
    │    └ <function _worker at 0x000002520E4EC1F8>
    └ <Thread(ThreadPoolExecutor-0_1, started daemon 3172)>

  File "C:\Users\admin\AppData\Local\Programs\Python\Python37\lib\concurrent\futures\thread.py", line 80, in _worker
    work_item.run()
    │         └ <function _WorkItem.run at 0x000002520E4EC318>
    └ <concurrent.futures.thread._WorkItem object at 0x000002520E66AC48>

  File "C:\Users\admin\AppData\Local\Programs\Python\Python37\lib\concurrent\futures\thread.py", line 57, in run
    result = self.fn(*self.args, **self.kwargs)
             │    │   │    │       │    └ {}
             │    │   │    │       └ <concurrent.futures.thread._WorkItem object at 0x000002520E66AC48>
             │    │   │    └ [<grpc._cython.cygrpc.RequestCallEvent object at 0x000002520E66B688>, <grpc._server._RPCState object at 0x000002520E66AB08>, ...
             │    │   └ <concurrent.futures.thread._WorkItem object at 0x000002520E66AC48>
             │    └ <function _unary_response_in_pool at 0x000002520E51C8B8>
             └ <concurrent.futures.thread._WorkItem object at 0x000002520E66AC48>

  File "D:\virtual-environment\py3.7\lib\site-packages\grpc\_server.py", line 561, in _unary_response_in_pool
    argument, request_deserializer)
    │         └ <built-in method FromString of GeneratedProtocolMessageType object at 0x000002520B7F1998>
    └ id: 3
      userId: 11

> File "D:\virtual-environment\py3.7\lib\site-packages\grpc\_server.py", line 443, in _call_behavior
    response_or_iterator = behavior(argument, context)
                           │        │         └ <grpc._server._Context object at 0x000002520E66AAC8>
                           │        └ id: 3
                           │          userId: 11
                           │          
                           └ <bound method MessageServicer.DeleteMessage of <user_operation_srv.handler.message.MessageServicer object at 0x000002520E4EF3...

  File "D:\PythonProjects\shop\user_operation_srv\handler\message.py", line 58, in DeleteMessage
    except DoesNotExist:

NameError: name 'DoesNotExist' is not defined
2022-05-18 17:21:41.714 | INFO     | __main__:on_exit:43 - 注销ab21bac6-d68a-11ec-8dcb-5800e3ca956e服务
2022-05-18 17:21:41.747 | INFO     | __main__:on_exit:45 - 服务注销成功
