2022-05-18 17:21:47.648 | INFO     | __main__:server:76 - 启动服务：192.168.23.1:57880
2022-05-18 17:21:47.653 | INFO     | __main__:server:79 - 服务注册开始
2022-05-18 17:21:47.688 | INFO     | __main__:server:86 - 服务注册成功
2022-05-18 17:21:56.852 | ERROR    | grpc._server:_call_behavior:443 - An error has been caught in function '_call_behavior', process 'MainProcess' (8728), thread 'ThreadPoolExecutor-0_1' (4872):
Traceback (most recent call last):

  File "C:\Users\admin\AppData\Local\Programs\Python\Python37\lib\threading.py", line 890, in _bootstrap
    self._bootstrap_inner()
    │    └ <function Thread._bootstrap_inner at 0x00000278136BFAF8>
    └ <Thread(ThreadPoolExecutor-0_1, started daemon 4872)>

  File "C:\Users\admin\AppData\Local\Programs\Python\Python37\lib\threading.py", line 926, in _bootstrap_inner
    self.run()
    │    └ <function Thread.run at 0x00000278136BF8B8>
    └ <Thread(ThreadPoolExecutor-0_1, started daemon 4872)>

  File "C:\Users\admin\AppData\Local\Programs\Python\Python37\lib\threading.py", line 870, in run
    self._target(*self._args, **self._kwargs)
    │    │        │    │        │    └ {}
    │    │        │    │        └ <Thread(ThreadPoolExecutor-0_1, started daemon 4872)>
    │    │        │    └ (<weakref at 0x000002781643BA48; to 'ThreadPoolExecutor' at 0x00000278162C4C08>, <_queue.SimpleQueue object at 0x00000278162C...
    │    │        └ <Thread(ThreadPoolExecutor-0_1, started daemon 4872)>
    │    └ <function _worker at 0x00000278162CE1F8>
    └ <Thread(ThreadPoolExecutor-0_1, started daemon 4872)>

  File "C:\Users\admin\AppData\Local\Programs\Python\Python37\lib\concurrent\futures\thread.py", line 80, in _worker
    work_item.run()
    │         └ <function _WorkItem.run at 0x00000278162CE318>
    └ <concurrent.futures.thread._WorkItem object at 0x0000027816429F08>

  File "C:\Users\admin\AppData\Local\Programs\Python\Python37\lib\concurrent\futures\thread.py", line 57, in run
    result = self.fn(*self.args, **self.kwargs)
             │    │   │    │       │    └ {}
             │    │   │    │       └ <concurrent.futures.thread._WorkItem object at 0x0000027816429F08>
             │    │   │    └ [<grpc._cython.cygrpc.RequestCallEvent object at 0x000002781643B5E8>, <grpc._server._RPCState object at 0x00000278162C4248>, ...
             │    │   └ <concurrent.futures.thread._WorkItem object at 0x0000027816429F08>
             │    └ <function _unary_response_in_pool at 0x00000278162FC8B8>
             └ <concurrent.futures.thread._WorkItem object at 0x0000027816429F08>

  File "D:\virtual-environment\py3.7\lib\site-packages\grpc\_server.py", line 561, in _unary_response_in_pool
    argument, request_deserializer)
    │         └ <built-in method FromString of GeneratedProtocolMessageType object at 0x00000278135B0BD8>
    └ id: 2
      userId: 11

> File "D:\virtual-environment\py3.7\lib\site-packages\grpc\_server.py", line 443, in _call_behavior
    response_or_iterator = behavior(argument, context)
                           │        │         └ <grpc._server._Context object at 0x0000027816429108>
                           │        └ id: 2
                           │          userId: 11
                           │          
                           └ <bound method MessageServicer.DeleteMessage of <user_operation_srv.handler.message.MessageServicer object at 0x00000278162CA1...

  File "D:\PythonProjects\shop\user_operation_srv\handler\message.py", line 58, in DeleteMessage
    return empty_pb2.Empty()

NameError: name 'empty_pb2' is not defined
2022-05-18 17:22:35.303 | INFO     | __main__:on_exit:43 - 注销f129ab54-d68b-11ec-8763-5800e3ca956e服务
2022-05-18 17:22:35.320 | INFO     | __main__:on_exit:45 - 服务注销成功
