2022-05-18 17:22:42.571 | INFO     | __main__:server:76 - 启动服务：192.168.23.1:58040
2022-05-18 17:22:42.592 | INFO     | __main__:server:79 - 服务注册开始
2022-05-18 17:22:42.650 | INFO     | __main__:server:86 - 服务注册成功
2022-05-18 17:22:46.854 | ERROR    | grpc._server:_call_behavior:443 - An error has been caught in function '_call_behavior', process 'MainProcess' (12292), thread 'ThreadPoolExecutor-0_0' (1648):
Traceback (most recent call last):

  File "D:\virtual-environment\py3.7\lib\site-packages\peewee.py", line 6970, in get
    return clone.execute(database)[0]
           │     │       └ None
           │     └ <function BaseQuery.execute at 0x0000018B8C258A68>
           └ <peewee.ModelSelect object at 0x0000018B8CACA048>

  File "D:\virtual-environment\py3.7\lib\site-packages\peewee.py", line 4339, in __getitem__
    return self.row_cache[item]
           │    │         └ 0
           │    └ []
           └ <peewee.ModelObjectCursorWrapper object at 0x0000018B8CAC1F48>

IndexError: list index out of range


During handling of the above exception, another exception occurred:


Traceback (most recent call last):

  File "D:\PythonProjects\shop\user_operation_srv\handler\message.py", line 56, in DeleteMessage
    user_message = Messages.get(Messages.user == request.userId, Messages.id == request.id)
                   │        │   │        │       │       │       │        │     │       └ <field property 'MessageRequest.id'>
                   │        │   │        │       │       │       │        │     └ id: 2
                   │        │   │        │       │       │       │        │       userId: 11
                   │        │   │        │       │       │       │        │       
                   │        │   │        │       │       │       │        └ <peewee.FieldAccessor object at 0x0000018B8B9A9B48>
                   │        │   │        │       │       │       └ <Model: Messages>
                   │        │   │        │       │       └ <field property 'MessageRequest.userId'>
                   │        │   │        │       └ id: 2
                   │        │   │        │         userId: 11
                   │        │   │        │         
                   │        │   │        └ <peewee.FieldAccessor object at 0x0000018B8C66B348>
                   │        │   └ <Model: Messages>
                   │        └ <classmethod object at 0x0000018B8C28EC48>
                   └ <Model: Messages>

  File "D:\virtual-environment\py3.7\lib\site-packages\peewee.py", line 6522, in get
    return sq.get()
           │  └ <function BaseModelSelect.get at 0x0000018B8C299EE8>
           └ <peewee.ModelSelect object at 0x0000018B8CACA688>

  File "D:\virtual-environment\py3.7\lib\site-packages\peewee.py", line 6975, in get
    (clone.model, sql, params))
     │     │      │    └ [False, 11, 2, 1, 0]
     │     │      └ 'SELECT `t1`.`id`, `t1`.`add_time`, `t1`.`update_time`, `t1`.`is_deleted`, `t1`.`user`, `t1`.`message_type`, `t1`.`subject`, ...
     │     └ <Model: Messages>
     └ <peewee.ModelSelect object at 0x0000018B8CACA048>

user_operation_srv.model.models.MessagesDoesNotExist: <Model: Messages> instance matching query does not exist:
SQL: SELECT `t1`.`id`, `t1`.`add_time`, `t1`.`update_time`, `t1`.`is_deleted`, `t1`.`user`, `t1`.`message_type`, `t1`.`subject`, `t1`.`text`, `t1`.`file` FROM `messages` AS `t1` WHERE (((`t1`.`is_deleted` = %s) AND (`t1`.`user` = %s)) AND (`t1`.`id` = %s)) LIMIT %s OFFSET %s
Params: [False, 11, 2, 1, 0]


During handling of the above exception, another exception occurred:


Traceback (most recent call last):

  File "C:\Users\admin\AppData\Local\Programs\Python\Python37\lib\threading.py", line 890, in _bootstrap
    self._bootstrap_inner()
    │    └ <function Thread._bootstrap_inner at 0x0000018B89C6FAF8>
    └ <Thread(ThreadPoolExecutor-0_0, started daemon 1648)>

  File "C:\Users\admin\AppData\Local\Programs\Python\Python37\lib\threading.py", line 926, in _bootstrap_inner
    self.run()
    │    └ <function Thread.run at 0x0000018B89C6F8B8>
    └ <Thread(ThreadPoolExecutor-0_0, started daemon 1648)>

  File "C:\Users\admin\AppData\Local\Programs\Python\Python37\lib\threading.py", line 870, in run
    self._target(*self._args, **self._kwargs)
    │    │        │    │        │    └ {}
    │    │        │    │        └ <Thread(ThreadPoolExecutor-0_0, started daemon 1648)>
    │    │        │    └ (<weakref at 0x0000018B8CADB548; to 'ThreadPoolExecutor' at 0x0000018B8CA60F48>, <_queue.SimpleQueue object at 0x0000018B8CA6...
    │    │        └ <Thread(ThreadPoolExecutor-0_0, started daemon 1648)>
    │    └ <function _worker at 0x0000018B8CA6C1F8>
    └ <Thread(ThreadPoolExecutor-0_0, started daemon 1648)>

  File "C:\Users\admin\AppData\Local\Programs\Python\Python37\lib\concurrent\futures\thread.py", line 80, in _worker
    work_item.run()
    │         └ <function _WorkItem.run at 0x0000018B8CA6C318>
    └ <concurrent.futures.thread._WorkItem object at 0x0000018B8CACAF48>

  File "C:\Users\admin\AppData\Local\Programs\Python\Python37\lib\concurrent\futures\thread.py", line 57, in run
    result = self.fn(*self.args, **self.kwargs)
             │    │   │    │       │    └ {}
             │    │   │    │       └ <concurrent.futures.thread._WorkItem object at 0x0000018B8CACAF48>
             │    │   │    └ [<grpc._cython.cygrpc.RequestCallEvent object at 0x0000018B8CADB2C8>, <grpc._server._RPCState object at 0x0000018B8BFD0448>, ...
             │    │   └ <concurrent.futures.thread._WorkItem object at 0x0000018B8CACAF48>
             │    └ <function _unary_response_in_pool at 0x0000018B8CA9C8B8>
             └ <concurrent.futures.thread._WorkItem object at 0x0000018B8CACAF48>

  File "D:\virtual-environment\py3.7\lib\site-packages\grpc\_server.py", line 561, in _unary_response_in_pool
    argument, request_deserializer)
    │         └ <built-in method FromString of GeneratedProtocolMessageType object at 0x0000018B89DFAB48>
    └ id: 2
      userId: 11

> File "D:\virtual-environment\py3.7\lib\site-packages\grpc\_server.py", line 443, in _call_behavior
    response_or_iterator = behavior(argument, context)
                           │        │         └ <grpc._server._Context object at 0x0000018B8CACA4C8>
                           │        └ id: 2
                           │          userId: 11
                           │          
                           └ <bound method MessageServicer.DeleteMessage of <user_operation_srv.handler.message.MessageServicer object at 0x0000018B8CA6F4...

  File "D:\PythonProjects\shop\user_operation_srv\handler\message.py", line 61, in DeleteMessage
    context.set_code(grpc.StatusCode.NOT_FOUND)
    │       └ <function _Context.set_code at 0x0000018B8CA99DC8>
    └ <grpc._server._Context object at 0x0000018B8CACA4C8>

NameError: name 'grpc' is not defined
2022-05-18 17:23:05.121 | INFO     | __main__:on_exit:43 - 注销11e656b4-d68c-11ec-a46e-5800e3ca956e服务
2022-05-18 17:23:05.135 | INFO     | __main__:on_exit:45 - 服务注销成功
