2022-05-17 18:01:46.282 | INFO     | __main__:server:76 - 启动服务：192.168.23.1:65361
2022-05-17 18:01:46.301 | INFO     | __main__:server:79 - 服务注册开始
2022-05-17 18:01:46.433 | INFO     | __main__:server:86 - 服务注册成功
2022-05-17 18:04:35.701 | ERROR    | grpc._server:_call_behavior:443 - An error has been caught in function '_call_behavior', process 'MainProcess' (8244), thread 'ThreadPoolExecutor-0_9' (13300):
Traceback (most recent call last):

  File "C:\Users\admin\AppData\Local\Programs\Python\Python37\lib\threading.py", line 890, in _bootstrap
    self._bootstrap_inner()
    │    └ <function Thread._bootstrap_inner at 0x0000025C926DFAF8>
    └ <Thread(ThreadPoolExecutor-0_9, started daemon 13300)>

  File "C:\Users\admin\AppData\Local\Programs\Python\Python37\lib\threading.py", line 926, in _bootstrap_inner
    self.run()
    │    └ <function Thread.run at 0x0000025C926DF8B8>
    └ <Thread(ThreadPoolExecutor-0_9, started daemon 13300)>

  File "C:\Users\admin\AppData\Local\Programs\Python\Python37\lib\threading.py", line 870, in run
    self._target(*self._args, **self._kwargs)
    │    │        │    │        │    └ {}
    │    │        │    │        └ <Thread(ThreadPoolExecutor-0_9, started daemon 13300)>
    │    │        │    └ (<weakref at 0x0000025C954787C8; to 'ThreadPoolExecutor' at 0x0000025C952DA1C8>, <_queue.SimpleQueue object at 0x0000025C952E...
    │    │        └ <Thread(ThreadPoolExecutor-0_9, started daemon 13300)>
    │    └ <function _worker at 0x0000025C952F99D8>
    └ <Thread(ThreadPoolExecutor-0_9, started daemon 13300)>

  File "C:\Users\admin\AppData\Local\Programs\Python\Python37\lib\concurrent\futures\thread.py", line 80, in _worker
    work_item.run()
    │         └ <function _WorkItem.run at 0x0000025C952F9AF8>
    └ <concurrent.futures.thread._WorkItem object at 0x0000025C95480C08>

  File "C:\Users\admin\AppData\Local\Programs\Python\Python37\lib\concurrent\futures\thread.py", line 57, in run
    result = self.fn(*self.args, **self.kwargs)
             │    │   │    │       │    └ {}
             │    │   │    │       └ <concurrent.futures.thread._WorkItem object at 0x0000025C95480C08>
             │    │   │    └ [<grpc._cython.cygrpc.RequestCallEvent object at 0x0000025C9547CF48>, <grpc._server._RPCState object at 0x0000025C95480B48>, ...
             │    │   └ <concurrent.futures.thread._WorkItem object at 0x0000025C95480C08>
             │    └ <function _unary_response_in_pool at 0x0000025C953270D8>
             └ <concurrent.futures.thread._WorkItem object at 0x0000025C95480C08>

  File "D:\virtual-environment\py3.7\lib\site-packages\grpc\_server.py", line 561, in _unary_response_in_pool
    argument, request_deserializer)
    │         └ <built-in method FromString of GeneratedProtocolMessageType object at 0x0000025C925FC488>
    └ userId: 11
      messageType: 1
      subject: "test"
      text: "test"

> File "D:\virtual-environment\py3.7\lib\site-packages\grpc\_server.py", line 443, in _call_behavior
    response_or_iterator = behavior(argument, context)
                           │        │         └ <grpc._server._Context object at 0x0000025C95480B88>
                           │        └ userId: 11
                           │          messageType: 1
                           │          subject: "test"
                           │          text: "test"
                           │          
                           └ <bound method MessageServicer.CreateMessage of <user_operation_srv.handler.message.MessageServicer object at 0x0000025C952FC0...

  File "D:\PythonProjects\shop\user_operation_srv\handler\message.py", line 32, in CreateMessage
    message = LeavingMessages()

NameError: name 'LeavingMessages' is not defined
